Workbook

Sheet Sommaire
A1: Champs Module Commercial — Parnass Phase 2
A2: Source : Discovery Renta d'Exploitation + Indexation Carburant 2026 + Renta Avril 2025
A4: Lecture du document
A5: Onglet « Champs » | B5: Vue détaillée des 71 champs identifiés, regroupés par bloc fonctionnel.
A6: Onglet « Synthèse blocs » | B6: Comptage par bloc et par localisation (commercial / référentiel / auto).
A7: Onglet « Référentiels » | B7: Liste des tables externes à créer pour soutenir le module.
A8: Code couleur « Existe déjà » | B8: Vert = oui · Orange = partiel · Rouge = non.
A9: Code couleur « Priorité MVP » | B9: Rouge = critique · Orange = élevée · Jaune = moyenne · Gris = faible.
A12: Compteurs globaux
A14: Total champs identifiés | B14: =COUNTA(Champs!C2:C72) -> 71
A15: Existe déjà | B15: =COUNTIF(Champs!G2:G72,"Oui") -> 7
A16: Partiellement présent | B16: =COUNTIF(Champs!G2:G72,"Partiel") -> 4
A17: À créer | B17: =COUNTIF(Champs!G2:G72,"Non") -> 60
A19: Champs Module Commercial (saisie) | B19: =COUNTIF(Champs!H2:H72,"Module commercial") + COUNTIF(Champs!H2:H72,"Module commercial (conditionnel)") + COUNTIF(Champs!H2:H72,"Module commercial (ou inféré du type semi)") -> 41
A20: Champs en table externe (référentiel) | B20: =COUNTA(Champs!C2:C72) - B19 - COUNTIF(Champs!H2:H72,"Auto-calculé (intégration PTV)") -> 29
A21: Champs auto-calculés | B21: =COUNTIF(Champs!H2:H72,"Auto-calculé (intégration PTV)") -> 1

Sheet Champs
A1: N° | B1: Bloc | C1: Champ | D1: Type de donnée | E1: Valeurs / exemples | F1: Poste(s) alimenté(s) | G1: Existe déjà ? | H1: Localisation recommandée | I1: Justification du choix | J1: Priorité MVP | K1: Source / commentaire
A2: 1 | B2: A · Identification & contrat | C2: Référence prestation | D2: Texte | E2: Ex. « GLS Trappes-Coudray » | F2: Identifiant | G2: Non | H2: Module commercial | I2: Identifie chaque presta dans listes, rapports, recettes. | J2: Critique | K2: Renta Avril 2025 ligne 15
A3: 2 | B3: A · Identification & contrat | C3: Client | D3: Référence | E3: Ex. CHRONOPOST CHILLY, CAT, GLS | F3: Indexation, casse, droits | G3: Non | H3: Référentiel Clients + lien commercial | I3: Donnée maîtresse — héritage de règles tarifaires. | J3: Critique | K3: Indexation Client 2026 col. A
A4: 3 | B4: A · Identification & contrat | C4: Contrat parent | D4: Référence | E4: Ex. « IVELI_FRIDF SR1 » | F4: Héritage tarif + indexation | G4: Non | H4: Référentiel Contrats + lien commercial | I4: Permet héritage auto des règles indexation / tarif. | J4: Critique | K4: Indexation Client 2026 col. B
A5: 4 | B5: A · Identification & contrat | C5: Code Facturation | D5: Texte | E5: CAT, CEVAGEN, CHCMZ | F5: Indexation, facturation | G5: Non | H5: Référentiel Contrats (hérité) | I5: Code court par contrat utilisé en indexation. | J5: Élevée | K5: Indexation Client 2026 col. C
A6: 5 | B6: A · Identification & contrat | C6: Date début presta | D6: Date | E6: 01/03/2026 | F6: CA, ventilation | G6: Non | H6: Module commercial | I6: « Date de chargement fait foi pour facturation » (Discovery Rev-CA). | J6: Critique | K6: Excel Rev-CA B25
A7: 6 | B7: A · Identification & contrat | C7: Date fin presta | D7: Date | E7: 31/03/2026 | F7: CA, ventilation | G7: Non | H7: Module commercial | I7: Bornes du contrat / de la presta. | J7: Critique
A8: 7 | B8: A · Identification & contrat | C8: Fréquence | D8: Énum | E8: Lundi-Vendredi / Hebdo / Quotidien / Mensuel / One-shot | F8: CA | G8: Non | H8: Module commercial | I8: Détermine la quantité × montant unitaire. | J8: Élevée | K8: Renta Avril 2025 B15
A9: 8 | B9: A · Identification & contrat | C9: Quantité (cycles) | D9: Nombre | E9: 5 (jours/sem.) · 20 (jours/mois) | F9: CA | G9: Non | H9: Module commercial | I9: CA = montant unitaire × quantité. | J9: Élevée | K9: Renta Avril 2025 D15
A10: 9 | B10: A · Identification & contrat | C10: Code déchargement / Badge | D10: Texte | E10: BADGE-042 | F10: Identification | G10: Oui | H10: Module commercial | I10: Conservé tel quel — déjà présent. | J10: Faible
A11: 10 | B11: A · Identification & contrat | C11: Notes / commentaires | D11: Texte libre | E11: Instructions particulières | F11: — | G11: Oui | H11: Module commercial | I11: Conservé tel quel — déjà présent. | J11: Faible
A12: 11 | B12: B · Tarification (CA) | C12: Type de tarif | D12: Énum | E12: Forfaitaire / TK / Taux horaire / Trinome | F12: CA | G12: Partiel | H12: Module commercial | I12: Existant à étendre : ajouter « Trinome » (Discovery). | J12: Critique | K12: Excel Rev-CA B10-B14
A13: 12 | B13: B · Tarification (CA) | C13: Montant unitaire | D13: € | E13: 477,50 € | F13: CA | G13: Oui | H13: Module commercial | I13: Champ existant — OK. | J13: Critique
A14: 13 | B14: B · Tarification (CA) | C14: Unité | D14: Énum | E14: Jour / Km / Heure / Forfait | F14: CA | G14: Partiel | H14: Module commercial | I14: Existant — étendre selon type de tarif. | J14: Critique
A15: 14 | B15: B · Tarification (CA) | C15: Km contractuel (TK) | D15: Nombre | E15: 62 km, 129 km | F15: CA + indexation | G15: Non | H15: Module commercial (conditionnel) | I15: Conditionnel si type = TK ou Trinome. | J15: Critique | K15: Indexation Client 2026 col. H « Valeur de Réf. »
A16: 15 | B16: B · Tarification (CA) | C16: Heures contractuelles | D16: Nombre | E16: 35 h | F16: CA | G16: Non | H16: Module commercial (conditionnel) | I16: Conditionnel si type = Taux horaire ou Trinome. | J16: Critique | K16: Excel Rev-CA B13
A17: 16 | B17: B · Tarification (CA) | C17: Forfait matériel (Trinome) | D17: € | E17: 500 € | F17: CA | G17: Non | H17: Module commercial (conditionnel) | I17: Conditionnel si type = Trinome. | J17: Élevée | K17: Excel Rev-CA B14
A18: 17 | B18: B · Tarification (CA) | C18: Règle de dépassement | D18: Énum | E18: Km supp / Tx horaire add. / Aucun | F18: CA | G18: Non | H18: Module commercial | I18: Convention atelier Discovery. | J18: Moyenne | K18: Excel Rev-CA B11
A19: 18 | B19: B · Tarification (CA) | C19: Règle répartition multi-ressources | D19: Énum | E19: Prorata h / Prorata km / Égalitaire / Conducteur principal seul | F19: CA + 06 | G19: Non | H19: Module commercial | I19: Question soulevée par Raphaela (commentaire Excel A24/A41). | J19: Élevée | K19: Excel Rev-CA commentaire A24
A20: 19 | B20: C · Indexation carburant | C20: Type de carburant | D20: Énum | E20: Gasoil B7 / GNV / GNL / HVO100 / Électrique | F20: Indexation, 03, 05 | G20: Non | H20: Référentiel Contrats (hérité) — override presta possible | I20: Stable au niveau contrat ; override exceptionnel. | J20: Critique | K20: Excel Rev-index B14
A21: 20 | B21: C · Indexation carburant | C21: Indice de référence | D21: Sélecteur | E21: CNR GO PRO M-1 / CNR Gasoil HTVA / PMM DIREM M-1 / CNR GNV / CNR fioul | F21: Indexation | G21: Non | H21: Référentiel Contrats (hérité) | I21: 5 indices CNR distincts + bascule DIREM (jan. 2026). | J21: Critique | K21: Indexation Client 2026 col. E
A22: 21 | B22: C · Indexation carburant | C22: Valeur de l'indice de référence | D22: Décimal | E22: 174,88 (CAT) · 1,1654 (Chronopost) | F22: Indexation | G22: Non | H22: Référentiel Contrats (hérité) | I22: Valeur figée au moment de la signature contrat. | J22: Critique | K22: Indexation Client 2026 col. D
A23: 22 | B23: C · Indexation carburant | C23: Date de l'indice de référence | D23: Date | E23: 01/01/2024 | F23: Indexation | G23: Non | H23: Référentiel Contrats (hérité) | I23: Date de l'indice base contractuelle. | J23: Critique
A24: 23 | B24: C · Indexation carburant | C24: Mode temporel | D24: Énum | E24: M / M-1 (majoritaire) / M-2 / Semaine | F24: Indexation | G24: Non | H24: Référentiel Contrats (hérité) | I24: Décalage temporel d'application de l'indice. | J24: Critique | K24: Restitution HTML §06
A25: 24 | B25: C · Indexation carburant | C25: Mode de facturation IGO | D25: Énum | E25: % Pied de facture / Sur Km | F25: Indexation | G25: Non | H25: Référentiel Contrats (hérité) | I25: Comment l'indexation est appliquée sur la facture. | J25: Critique | K25: Indexation Client 2026 col. G
A26: 25 | B26: C · Indexation carburant | C26: Pondération | D26: % ou L/100km | E26: 0,25 (25%) · 0,28 · ou conso × km | F26: Indexation | G26: Non | H26: Référentiel Contrats (hérité) | I26: % du forfait OU L/100km × km contractuels. | J26: Critique | K26: Indexation Client 2026 col. F
A27: 26 | B27: C · Indexation carburant | C27: Cas particulier client | D27: Énum | E27: Standard / Auchan TIPCE / FedEx par presta / Aucun | F27: Indexation | G27: Non | H27: Référentiel Contrats + override Module Commercial (FedEx) | I27: Auchan = remise TIPCE · FedEx = saisie par presta. | J27: Élevée | K27: Restitution HTML §06
A28: 27 | B28: C · Indexation carburant | C28: Indices CNR/DIREM mensuels | D28: Numérique (table) | E28: 192,03 (CNR GO pro nov-25) · 1,3882 (DIREM PMM) | F28: Indexation | G28: Non | H28: Référentiel Indices (alimentation API CNR + DIREM) | I28: Données externes mensuelles, hors présence commercial. | J28: Critique | K28: Indexation Carburant 2026 onglet « indice »
A29: 28 | B29: D · Véhicule prévu | C29: Type tracteur requis | D29: Énum | E29: Tracteur GO / Tracteur GNC / Porteur SWAP GO / Porteur SWAP GNC / VL | F29: 01, 03, 05, 09, 10, 11 | G29: Non | H29: Module commercial | I29: Choix du commercial par presta. | J29: Critique | K29: Renta Avril 2025 « Liste » A1-A5
A30: 29 | B30: D · Véhicule prévu | C30: Conso prévue 100 km | D30: Nombre | E30: TRAGO 28 L · TRAGZ 30,5 kg · PORGO 30 L · PORGZ 33 kg | F30: 03 | G30: Non | H30: Référentiel Véhicules (préremplie auto) | I30: Stable, modifiable en exception. | J30: Élevée | K30: Renta Avril 2025 « Liste » col. H + Excel Coût-Carburants B10-C11
A31: 30 | B31: D · Véhicule prévu | C31: Type(s) de tracté (jusqu'à 4) | D31: Multi-énum | E31: Aérienne (Bachée/Classique/Frigo/Méga) / SR (Classique/Frigo/Méga/PC) / Remorque SWAP / Aucune | F31: 02, 09, 10, 11 | G31: Non | H31: Module commercial + Référentiel Véhicules | I31: Choix par presta — jusqu'à 4 tractés possibles. | J31: Critique | K31: Renta Avril 2025 « Liste » A7-A15
A32: 31 | B32: D · Véhicule prévu | C32: Allocation tracté | D32: Énum | E32: Plein temps client / Débord 100% client / Partagé | F32: 02 | G32: Non | H32: Module commercial | I32: Convention Discovery — détermine le coût alloué. | J32: Élevée | K32: Excel Coût-Tractés B20-C20
A33: 32 | B33: D · Véhicule prévu | C33: Frigo requis | D33: Booléen | E33: Oui / Non | F33: 04 | G33: Partiel | H33: Module commercial (ou inféré du type semi) | I33: Active poste 04 ; déjà partiellement via Contrainte Conducteur. | J33: Critique
A34: 33 | B34: D · Véhicule prévu | C34: Heures fonctionnement frigo | D34: Nombre (h) | E34: 50 h/mois | F34: 04 | G34: Non | H34: Module commercial (conditionnel) | I34: Conditionnel si frigo = oui. | J34: Critique | K34: Excel Coût-Fioul B13
A35: 34 | B35: D · Véhicule prévu | C35: Km à vide planifiés | D35: Nombre | E35: 80 km / cycle | F35: 03 | G35: Non | H35: Module commercial | I35: Distinguer du km productif. | J35: Élevée | K35: Excel Coût-Carburants D14
A36: 35 | B36: D · Véhicule prévu | C36: Loyer mensuel véhicule | D36: € | E36: 2 300 € (Tracteur GO) · 1 200 € (Aérienne) | F36: 01, 02 | G36: Non | H36: Référentiel Véhicules (table tarifaire) | I36: Tarif par type — stable. | J36: Critique | K36: Renta Avril 2025 « Liste » col. D
A37: 36 | B37: D · Véhicule prévu | C37: Tx Entretien €/km | D37: €/km | E37: 0,025 (Tracteur GO) · 0,035 (Tracteur GNC) | F37: 09 | G37: Non | H37: Référentiel Véhicules | I37: Tarif par type — stable. | J37: Critique | K37: Renta Avril 2025 « Liste » col. G
A38: 37 | B38: D · Véhicule prévu | C38: Tx Pneumatiques €/km | D38: €/km | E38: 0,025 (Tracteur GO) | F38: 10 | G38: Non | H38: Référentiel Véhicules | I38: Tarif par type — stable. | J38: Critique | K38: Renta Avril 2025 « Liste » col. F
A39: 38 | B39: D · Véhicule prévu | C39: Forfait assurance mensuel | D39: € | E39: Inclus dans loyer | F39: 11 | G39: Non | H39: Référentiel Véhicules | I39: Loyer = loyer + assurance + géoloc (note Renta). | J39: Élevée | K39: Renta Avril 2025 « Liste » A17
A40: 39 | B40: D · Véhicule prévu | C40: Coût géoloc mensuel | D40: € | E40: Inclus dans loyer | F40: Géoloc | G40: Non | H40: Référentiel Véhicules | I40: Inclus dans le loyer agrégé. | J40: Moyenne
...

Sheet Synthèse blocs
A1: Synthèse par bloc fonctionnel
A3: Bloc | B3: Libellé | C3: Total champs | D3: Existe déjà | E3: Partiel | F3: Non | G3: Critique MVP | H3: Élevée MVP
A4: A | B4: Identification & contrat | C4: =COUNTIF(Champs!B:B,"A · Identification & contrat") -> 10 | D4: =COUNTIFS(Champs!B:B,"A · Identification & contrat",Champs!G:G,"Oui") -> 2 | E4: =COUNTIFS(Champs!B:B,"A · Identification & contrat",Champs!G:G,"Partiel") -> 0 | F4: =COUNTIFS(Champs!B:B,"A · Identification & contrat",Champs!G:G,"Non") -> 8 | G4: =COUNTIFS(Champs!B:B,"A · Identification & contrat",Champs!J:J,"Critique") -> 5 | H4: =COUNTIFS(Champs!B:B,"A · Identification & contrat",Champs!J:J,"Élevée") -> 3
A5: B | B5: Tarification (CA) | C5: =COUNTIF(Champs!B:B,"B · Tarification (CA)") -> 8 | D5: =COUNTIFS(Champs!B:B,"B · Tarification (CA)",Champs!G:G,"Oui") -> 1 | E5: =COUNTIFS(Champs!B:B,"B · Tarification (CA)",Champs!G:G,"Partiel") -> 2 | F5: =COUNTIFS(Champs!B:B,"B · Tarification (CA)",Champs!G:G,"Non") -> 5 | G5: =COUNTIFS(Champs!B:B,"B · Tarification (CA)",Champs!J:J,"Critique") -> 5 | H5: =COUNTIFS(Champs!B:B,"B · Tarification (CA)",Champs!J:J,"Élevée") -> 2
A6: C | B6: Indexation carburant | C6: =COUNTIF(Champs!B:B,"C · Indexation carburant") -> 9 | D6: =COUNTIFS(Champs!B:B,"C · Indexation carburant",Champs!G:G,"Oui") -> 0 | E6: =COUNTIFS(Champs!B:B,"C · Indexation carburant",Champs!G:G,"Partiel") -> 0 | F6: =COUNTIFS(Champs!B:B,"C · Indexation carburant",Champs!G:G,"Non") -> 9 | G6: =COUNTIFS(Champs!B:B,"C · Indexation carburant",Champs!J:J,"Critique") -> 8 | H6: =COUNTIFS(Champs!B:B,"C · Indexation carburant",Champs!J:J,"Élevée") -> 1
A7: D | B7: Véhicule prévu | C7: =COUNTIF(Champs!B:B,"D · Véhicule prévu") -> 12 | D7: =COUNTIFS(Champs!B:B,"D · Véhicule prévu",Champs!G:G,"Oui") -> 0 | E7: =COUNTIFS(Champs!B:B,"D · Véhicule prévu",Champs!G:G,"Partiel") -> 1 | F7: =COUNTIFS(Champs!B:B,"D · Véhicule prévu",Champs!G:G,"Non") -> 11 | G7: =COUNTIFS(Champs!B:B,"D · Véhicule prévu",Champs!J:J,"Critique") -> 7 | H7: =COUNTIFS(Champs!B:B,"D · Véhicule prévu",Champs!J:J,"Élevée") -> 4
A8: E | B8: Conducteur prévu | C8: =COUNTIF(Champs!B:B,"E · Conducteur prévu") -> 12 | D8: =COUNTIFS(Champs!B:B,"E · Conducteur prévu",Champs!G:G,"Oui") -> 1 | E8: =COUNTIFS(Champs!B:B,"E · Conducteur prévu",Champs!G:G,"Partiel") -> 0 | F8: =COUNTIFS(Champs!B:B,"E · Conducteur prévu",Champs!G:G,"Non") -> 11 | G8: =COUNTIFS(Champs!B:B,"E · Conducteur prévu",Champs!J:J,"Critique") -> 3 | H8: =COUNTIFS(Champs!B:B,"E · Conducteur prévu",Champs!J:J,"Élevée") -> 6
A9: F | B9: Trajet & péages | C9: =COUNTIF(Champs!B:B,"F · Trajet & péages") -> 5 | D9: =COUNTIFS(Champs!B:B,"F · Trajet & péages",Champs!G:G,"Oui") -> 0 | E9: =COUNTIFS(Champs!B:B,"F · Trajet & péages",Champs!G:G,"Partiel") -> 1 | F9: =COUNTIFS(Champs!B:B,"F · Trajet & péages",Champs!G:G,"Non") -> 4 | G9: =COUNTIFS(Champs!B:B,"F · Trajet & péages",Champs!J:J,"Critique") -> 3 | H9: =COUNTIFS(Champs!B:B,"F · Trajet & péages",Champs!J:J,"Élevée") -> 2
A10: G | B10: Équipements | C10: =COUNTIF(Champs!B:B,"G · Équipements") -> 6 | D10: =COUNTIFS(Champs!B:B,"G · Équipements",Champs!G:G,"Oui") -> 3 | E10: =COUNTIFS(Champs!B:B,"G · Équipements",Champs!G:G,"Partiel") -> 0 | F10: =COUNTIFS(Champs!B:B,"G · Équipements",Champs!G:G,"Non") -> 3 | G10: =COUNTIFS(Champs!B:B,"G · Équipements",Champs!J:J,"Critique") -> 0 | H10: =COUNTIFS(Champs!B:B,"G · Équipements",Champs!J:J,"Élevée") -> 3
A11: H | B11: Sous-traitance | C11: =COUNTIF(Champs!B:B,"H · Sous-traitance") -> 5 | D11: =COUNTIFS(Champs!B:B,"H · Sous-traitance",Champs!G:G,"Oui") -> 0 | E11: =COUNTIFS(Champs!B:B,"H · Sous-traitance",Champs!G:G,"Partiel") -> 0 | F11: =COUNTIFS(Champs!B:B,"H · Sous-traitance",Champs!G:G,"Non") -> 5 | G11: =COUNTIFS(Champs!B:B,"H · Sous-traitance",Champs!J:J,"Critique") -> 2 | H11: =COUNTIFS(Champs!B:B,"H · Sous-traitance",Champs!J:J,"Élevée") -> 2
A12: I | B12: Conventions de calcul | C12: =COUNTIF(Champs!B:B,"I · Conventions de calcul") -> 4 | D12: =COUNTIFS(Champs!B:B,"I · Conventions de calcul",Champs!G:G,"Oui") -> 0 | E12: =COUNTIFS(Champs!B:B,"I · Conventions de calcul",Champs!G:G,"Partiel") -> 0 | F12: =COUNTIFS(Champs!B:B,"I · Conventions de calcul",Champs!G:G,"Non") -> 4 | G12: =COUNTIFS(Champs!B:B,"I · Conventions de calcul",Champs!J:J,"Critique") -> 1 | H12: =COUNTIFS(Champs!B:B,"I · Conventions de calcul",Champs!J:J,"Élevée") -> 3
B13: TOTAL | C13: =SUM(C4:C12) -> 71 | D13: =SUM(D4:D12) -> 7 | E13: =SUM(E4:E12) -> 4 | F13: =SUM(F4:F12) -> 60 | G13: =SUM(G4:G12) -> 34 | H13: =SUM(H4:H12) -> 26
A16: Synthèse par localisation recommandée
A18: Localisation | B18: Nombre de champs
A19: Module commercial | B19: =COUNTIF(Champs!H:H,A19) -> 36
A20: Module commercial (conditionnel) | B20: =COUNTIF(Champs!H:H,A20) -> 4
A21: Module commercial + Référentiel Clients | B21: =COUNTIF(Champs!H:H,A21) -> 0
A22: Module commercial + Référentiel Sous-traitants | B22: =COUNTIF(Champs!H:H,A22) -> 1
A23: Module commercial + Référentiel Véhicules | B23: =COUNTIF(Champs!H:H,A23) -> 1
A24: Module commercial (ou inféré du type semi) | B24: =COUNTIF(Champs!H:H,A24) -> 1
A25: Référentiel Clients + lien commercial | B25: =COUNTIF(Champs!H:H,A25) -> 1
A26: Référentiel Contrats + lien commercial | B26: =COUNTIF(Champs!H:H,A26) -> 1
A27: Référentiel Contrats (hérité) | B27: =COUNTIF(Champs!H:H,A27) -> 7
A28: Référentiel Contrats (hérité) — override presta possible | B28: =COUNTIF(Champs!H:H,A28) -> 1
A29: Référentiel Contrats + override Module Commercial (FedEx) | B29: =COUNTIF(Champs!H:H,A29) -> 1
A30: Référentiel Véhicules | B30: =COUNTIF(Champs!H:H,A30) -> 4
... A37: Auto-calculé (intégration PTV) | B37: =COUNTIF(Champs!H:H,A37) -> 1

Sheet Référentiels
A1: Tables externes à créer (référentiels)
A3: Le module commercial s'appuie sur 9 référentiels externes (tables maîtres).
A5: # | B5: Référentiel | C5: Contenu | D5: Fréquence MAJ | E5: Source / propriétaire
A6: 1 | B6: Référentiel Clients | C6: ID client · raison sociale · groupes (CAT, CEVA, CHRONOPOST, GLS, DHL, UPS, FedEx, Auchan…) | D6: Ad hoc | E6: Commercial — Laurent
A7: 2 | B7: Référentiel Contrats | C7: ID contrat · client · libellé · code facturation · règles tarif par défaut · règles indexation par défaut | D7: Ad hoc (à chaque nouveau contrat / fin de contrat) | E7: Commercial — Laurent
A8: 3 | B8: Référentiel Véhicules | C8: Type tracteur (TRAGO/TRAGZ/PORGO/PORGZ/VL) · type semi · loyer mensuel · conso 100 km · Tx Pneu €/km · Tx Entretien €/km · assurance | D8: Annuelle (MAJ contrats LLD) | E8: Parc — Raphael · MyRentCar
A9: 4 | B9: Référentiel Conducteurs / Profils | C9: Profils VL/CM/SPL/Polyvalent · taux journalier · primes (nuit / dimanche / découcher / panier) · frais hôtel | D9: Annuelle (NAO) + ad hoc | E9: RH / Paye — Mathieu
A10: 5 | B10: Référentiel Énergies | C10: Code énergie (Gasoil B7 / GNV / GNL / HVO100 / Électrique) · unité (L, kg) · table d'indexation associée | D10: Annuelle | E10: Indexation — Laurent
A11: 6 | B11: Référentiel Indices CNR + DIREM | C11: 5 indices CNR (GO pro / GO HTVA / Cuve moy. / GNV / fioul) + 2 indices DIREM (PMM / fin de mois) · historique janvier 2000 → courant | D11: Mensuelle (CNR API · DIREM Excel hebdo) | E11: Externe — CNR + DIREM
A12: 7 | B12: Référentiel Équipements | C12: Tirpalette · chariot élévateur · hayon · ADR · APSAD P3 · APSAD P5 · BPD · Frigo · coût mensuel par équipement | D12: Annuelle (renégoc. fournisseurs) | E12: Parc — Raphael · MyRentCar
A13: 8 | B13: Référentiel Sous-traitants | C13: ID sous-traitant · raison sociale · zones desservies · taux moyen · qualité | D13: Ad hoc | E13: Exploitation — Housam
A14: 9 | B14: Référentiel Conventions de calcul | C14: Diviseur 21 j (H1) · conso AdBlue 1,9 L/100 km · prix AdBlue 0,42 €/L · conso frigo 2 L/h · taux casse ≈ 1,4 % | D14: Trimestrielle / ad hoc | E14: Discovery — Mathieu / Laurent
