Workbook

Sheet indice Carburant
A1: INDICE 2026
E4: DIREM
A5: CNR Base 100 Décembre 2000 | B5: 45931 | C5: 45962 | D5: 45992 | E5: 46023 | F5: 46054 | G5: 46082 | H5: 46113 | I5: 46143 | J5: 46174 | K5: 46204 | L5: 46235 | M5: 46266 | N5: 46296 | O5: 46327 | P5: 46357
A6: Indice CNR gazole professionnel | B6: 183.84 | C6: 192.03 | D6: 181.52 | E6: 187.66 | F6: 193.34 | G6: 248.08
A7: Indice CNR gazole hors TVA | B7: 192.92 | C7: 200.49 | D7: 190.79 | E7: 196.16 | F7: 201.41 | G7: 251.94
A8: Prix CNR gazole CUVE moyenne mensuelle | B8: 1.2965 | C8: 1.345 | D8: 1.2687 | E8: 1.3218 | F8: 1.3547 | G8: 1.7575
A9: Prix CNR gazole cuve fin de mois | B9: 1.3111 | C9: 1.34 | D9: 1.2472 | E9: - | F9: - | G9: - | H9: - | I9: - | J9: - | K9: - | L9: - | M9: - | N9: - | O9: - | P9: -
A10: Prix gazole POMPE moyenne mensuelle (DIREM) | B10: 1.3322 | C10: 1.3882 | D10: 1.3384 | E10: 1.362 | F10: 1.3937 | G10: 1.7224 | Q10: DIREM à partir de Janvier 2026
A11: Prix gazole pompe fin de mois (DIREM) | B11: 1.3253 | C11: 1.4141 | D11: 1.2749 | E11: 1.3663 | F11: 1.3748 | G11: 1.7573
A13: Indice CNR carburant GNV | B13: 165.31 | C13: 166.16 | D13: 161.43 | E13: 159.61 | F13: 177.68
A14: ENGIE Hors TICGN COMPTE VIAPOST | B14: 1.004 | C14: 0.9954 | D14: 0.9834 | E14: 0.9356 | F14: 1.03
A15: AS 24 - Carburant BIO GNC - Tarif PARNASS | B15: 1.1409 | C15: 1.1408 | D15: 1.1408 | E15: 1.1008 | F15: 1.2192 | G15: 1.1983
A16: ENGIE - Carburant GNC L - Tarif PARNASS | B16: 1.2241 | C16: 1.2156 | D16: 1.2043 | E16: 1.156 | F16: 1.251 | G16: 1.2264 | H16: 1.5505
A17: ENGIE - Carburant BIO GNC - Tarif PARNASS | B17: 1.2246 | C17: 1.2159 | D17: 1.2019 | E17: 1.1962 | F17: 1.3068 | G17: 1.28031 | H17: 1.5859
A18: ENGIE - Carburant GNL - Tarif PARNASS | B18: 1.1788 | C18: 1.1703 | D18: 1.1588 | E18: 1.1105 | F18: 1.2053 | G18: 1.1806 | H18: 1.5032
A20: AS 24 - Carburant GO - Tarif PARNASS | B20: 1.3925 | C20: 1.4562 | D20: 1.3838 | E20: 1.3995 | F20: 1.4348 | G20: 1.8088
A22: Indice CNR Carburant groupe froid autonome GNR | B22: 272.73 | C22: 289.28 | D22: 268.99 | E22: 282.47 | F22: 297.24 | G22: 393.85
A25: Remise Partiel TICPE Forfait | B25: 0.1571 | C25: 0.1571 | D25: 0.1571 | E25: 0.1575 | F25: 0.1575 | G25: 0.1575 | H25: 0.1575 | I25: 0.1575 | J25: 0.1575 | K25: 0.1575 | L25: 0.1575 | M25: 0.1575 | N25: 0.1575 | O25: 0.1575 | P25: 0.1575
A26: REMISE PARTIEL TICPE AUCHAN | E26: 0.1556 | F26: 0.1556 | G26: 0.1556 | H26: 0.1556 | I26: 0.1556 | J26: 0.1556 | K26: 0.1556 | L26: 0.1556 | M26: 0.1556 | N26: 0.1556 | O26: 0.1556 | P26: 0.1556

Sheet Indexation Client 2026
A1: INDEXATION CARBURANT Clients 2026
G2: Jours | H2: Ouvrables | J2: 26 | K2: 24 | L2: 26 | M2: 25 | N2: 22 | O2: 26 | P2: 26 | Q2: 25 | R2: 26 | S2: 27 | T2: 24 | U2: 26
H3: Ouvrés | J3: 21 | K3: 20 | L3: 22 | M3: 21 | N3: 17 | O3: 22 | P3: 22 | Q3: 21 | R3: 22 | S3: 22 | T3: 20 | U3: 22
A5: CLIENTS | B5: Contrats | C5: Code Facturation | D5: Indice de Référence | E5: Base indice | F5: Pondération | G5: Mode de Facturation IGO | H5: Valeur de Réf. | J5: 46023 | K5: 46054 | L5: 46082 | M5: 46113 | N5: 46143 | O5: 46174 | P5: 46204 | Q5: 46235 | R5: 46266 | S5: 46296 | T5: 46327 | U5: 46357
A6: CAT | B6: IVELI_FRIDF SR1 | C6: CAT | D6: 174.88 | E6: CNR GO PRO M-1 | F6: 0.25 | G6: % Pied de facture | J6: =((('indice Carburant'!D6/'Indexation Client 2026'!$D$6)-1)*'Indexation Client 2026'!$F$6) -> 0.0094922232 | K6: =((('indice Carburant'!E6/'Indexation Client 2026'!$D$6)-1)*'Indexation Client 2026'!$F$6) -> 0.018269671 | L6: =((('indice Carburant'!F6/'Indexation Client 2026'!$D$6)-1)*'Indexation Client 2026'!$F$6) -> 0.026389524 | M6: =((('indice Carburant'!G6/'Indexation Client 2026'!$D$6)-1)*'Indexation Client 2026'!$F$6) -> 0.10464318 | N6: =((('indice Carburant'!H6/'Indexation Client 2026'!$D$6)-1)*'Indexation Client 2026'!$F$6) -> -0.25 | O6: =((('indice Carburant'!I6/'Indexation Client 2026'!$D$6)-1)*'Indexation Client 2026'!$F$6) -> -0.25 | P6: =((('indice Carburant'!J6/'Indexation Client 2026'!$D$6)-1)*'Indexation Client 2026'!$F$6) -> -0.25 | Q6: =((('indice Carburant'!K6/'Indexation Client 2026'!$D$6)-1)*'Indexation Client 2026'!$F$6) -> -0.25 | ... U6: =((('indice Carburant'!O6/'Indexation Client 2026'!$D$6)-1)*'Indexation Client 2026'!$F$6) -> -0.25
A7: CAT | B7: JCBBO_FRIDF | C7: CAT | D7: 174.88 | E7: CNR GO PRO M-1 | F7: 0.25 | G7: % Pied de facture | J7: =((('indice Carburant'!D6/'Indexation Client 2026'!$D$7)-1)*'Indexation Client 2026'!$F$7) -> 0.0094922232 | K7: =((('indice Carburant'!E6/'Indexation Client 2026'!$D$7)-1)*'Indexation Client 2026'!$F$7) -> 0.018269671 | L7: =((('indice Carburant'!F6/'Indexation Client 2026'!$D$7)-1)*'Indexation Client 2026'!$F$7) -> 0.026389524 | M7: =((('indice Carburant'!G6/'Indexation Client 2026'!$D$7)-1)*'Indexation Client 2026'!$F$7) -> 0.10464318 | N7: =((('indice Carburant'!H6/'Indexation Client 2026'!$D$7)-1)*'Indexation Client 2026'!$F$7) -> -0.25 | O7: =((('indice Carburant'!I6/'Indexation Client 2026'!$D$7)-1)*'Indexation Client 2026'!$F$7) -> -0.25 | P7: =((('indice Carburant'!J6/'Indexation Client 2026'!$D$7)-1)*'Indexation Client 2026'!$F$7) -> -0.25 | Q7: =((('indice Carburant'!K6/'Indexation Client 2026'!$D$7)-1)*'Indexation Client 2026'!$F$7) -> -0.25 | ... U7: =((('indice Carburant'!O6/'Indexation Client 2026'!$D$7)-1)*'Indexation Client 2026'!$F$7) -> -0.25
A8: CEVA LOGISTIC | B8: CEVA GENNEVILLIERS | C8: CEVAGEN | D8: ?
A9: CEVA LOGISTIC | B9: CEVA MOISSY | C9: CEVAMOI | D9: ?
A10: CHRONOPOST CHILLY | B10: 40U62 - Conforma / MGF | C10: CHCMZ | D10: 1.1654 | E10: PMM DIREM M-1 | F10: 0.28 | G10: Sur Km | H10: 62 | J10: =(('indice Carburant'!D10-'Indexation Client 2026'!$D$10)*'Indexation Client 2026'!$F$10)*'Indexation Client 2026'!$H$10 -> 3.00328 | K10: =(('indice Carburant'!E10-'Indexation Client 2026'!$D$10)*'Indexation Client 2026'!$F$10)*'Indexation Client 2026'!$H$10 -> 3.412976 | L10: =(('indice Carburant'!F10-'Indexation Client 2026'!$D$10)*'Indexation Client 2026'!$F$10)*'Indexation Client 2026'!$H$10 -> 3.963288 | M10: =(('indice Carburant'!G10-'Indexation Client 2026'!$D$10)*'Indexation Client 2026'!$F$10)*'Indexation Client 2026'!$H$10 -> 9.66952 | N10: =(('indice Carburant'!H10-'Indexation Client 2026'!$D$10)*'Indexation Client 2026'!$F$10)*'Indexation Client 2026'!$H$10 -> -20.231344 | O10: =(('indice Carburant'!I10-'Indexation Client 2026'!$D$10)*'Indexation Client 2026'!$F$10)*'Indexation Client 2026'!$H$10 -> -20.231344 | P10: =(('indice Carburant'!J10-'Indexation Client 2026'!$D$10)*'Indexation Client 2026'!$F$10)*'Indexation Client 2026'!$H$10 -> -20.231344 | Q10: =(('indice Carburant'!K10-'Indexation Client 2026'!$D$10)*'Indexation Client 2026'!$F$10)*'Indexation Client 2026'!$H$10 -> -20.231344 | ... U10: =(('indice Carburant'!O10-'Indexation Client 2026'!$D$10)*'Indexation Client 2026'!$F$10)*'Indexation Client 2026'!$H$10 -> -20.231344
A11: CHRONOPOST CHILLY | B11: 40U71 - Alloga | C11: CHCMZ | D11: 1.6915 | E11: PMM DIREM M-1 | F11: 0.28 | G11: Sur Km | H11: 129 | J11: =(('indice Carburant'!D10-'Indexation Client 2026'!$D$11)*'Indexation Client 2026'!$F$11)*'Indexation Client 2026'!$H$11 -> -12.753972 | K11: =(('indice Carburant'!E10-'Indexation Client 2026'!$D$11)*'Indexation Client 2026'!$F$11)*'Indexation Client 2026'!$H$11 -> -11.90154 | L11: =(('indice Carburant'!F10-'Indexation Client 2026'!$D$11)*'Indexation Client 2026'!$F$11)*'Indexation Client 2026'!$H$11 -> -10.756536 | M11: =(('indice Carburant'!G10-'Indexation Client 2026'!$D$11)*'Indexation Client 2026'!$F$11)*'Indexation Client 2026'!$H$11 -> 1.116108 | N11: =(('indice Carburant'!H10-'Indexation Client 2026'!$D$11)*'Indexation Client 2026'!$F$11)*'Indexation Client 2026'!$H$11 -> -61.09698 | O11: =(('indice Carburant'!I10-'Indexation Client 2026'!$D$11)*'Indexation Client 2026'!$F$11)*'Indexation Client 2026'!$H$11 -> -61.09698 | P11: =(('indice Carburant'!J10-'Indexation Client 2026'!$D$11)*'Indexation Client 2026'!$F$11)*'Indexation Client 2026'!$H$11 -> -61.09698 | Q11: =(('indice Carburant'!K10-'Indexation Client 2026'!$D$11)*'Indexation Client 2026'!$F$11)*'Indexation Client 2026'!$H$11 -> -61.09698 | ... U11: =(('indice Carburant'!O10-'Indexation Client 2026'!$D$11)*'Indexation Client 2026'!$F$11)*'Indexation Client 2026'!$H$11 -> -61.09698
A12: CHRONOPOST CHILLY | B12: 40U72 - Dyson | C12: CHCMZ | D12: 1.2187 | E12: PMM DIREM M-1 | F12: 0.28 | G12: Sur Km | H12: 129 | J12: =(('indice Carburant'!D10-'Indexation Client 2026'!$D$12)*'Indexation Client 2026'!$F$12)*'Indexation Client 2026'!$H$12 -> 4.323564 | K12: =(('indice Carburant'!E10-'Indexation Client 2026'!$D$12)*'Indexation Client 2026'!$F$12)*'Indexation Client 2026'!$H$12 -> 5.175996 | L12: =(('indice Carburant'!F10-'Indexation Client 2026'!$D$12)*'Indexation Client 2026'!$F$12)*'Indexation Client 2026'!$H$12 -> 6.321 | M12: =(('indice Carburant'!G10-'Indexation Client 2026'!$D$12)*'Indexation Client 2026'!$F$12)*'Indexation Client 2026'!$H$12 -> 18.193644 | N12: =(('indice Carburant'!H10-'Indexation Client 2026'!$D$12)*'Indexation Client 2026'!$F$12)*'Indexation Client 2026'!$H$12 -> -44.019444 | O12: =(('indice Carburant'!I10-'Indexation Client 2026'!$D$12)*'Indexation Client 2026'!$F$12)*'Indexation Client 2026'!$H$12 -> -44.019444 | P12: =(('indice Carburant'!J10-'Indexation Client 2026'!$D$12)*'Indexation Client 2026'!$F$12)*'Indexation Client 2026'!$H$12 -> -44.019444 | Q12: =(('indice Carburant'!K10-'Indexation Client 2026'!$D$12)*'Indexation Client 2026'!$F$12)*'Indexation Client 2026'!$H$12 -> -44.019444 | ... U12: =(('indice Carburant'!O10-'Indexation Client 2026'!$D$12)*'Indexation Client 2026'!$F$12)*'Indexation Client 2026'!$H$12 -> -44.019444
A13: CHRONOPOST CHILLY | B13: 40U76 - AMAZON (HNI) | C13: CHCMZ | D13: 1.376 | E13: PMM DIREM M-1 | F13: 0.28 | G13: Sur Km | H13: 64 | J13: =(('indice Carburant'!D10-'Indexation Client 2026'!$D$13)*'Indexation Client 2026'!$F$13)*'Indexation Client 2026'!$H$13 -> -0.673792 | K13: =(('indice Carburant'!E10-'Indexation Client 2026'!$D$13)*'Indexation Client 2026'!$F$13)*'Indexation Client 2026'!$H$13 -> -0.25088 | L13: =(('indice Carburant'!F10-'Indexation Client 2026'!$D$13)*'Indexation Client 2026'!$F$13)*'Indexation Client 2026'!$H$13 -> 0.317184 | M13: =(('indice Carburant'!G10-'Indexation Client 2026'!$D$13)*'Indexation Client 2026'!$F$13)*'Indexation Client 2026'!$H$13 -> 6.207488 | N13: =(('indice Carburant'!H10-'Indexation Client 2026'!$D$13)*'Indexation Client 2026'!$F$13)*'Indexation Client 2026'!$H$13 -> -24.65792 | O13: =(('indice Carburant'!I10-'Indexation Client 2026'!$D$13)*'Indexation Client 2026'!$F$13)*'Indexation Client 2026'!$H$13 -> -24.65792 | P13: =(('indice Carburant'!J10-'Indexation Client 2026'!$D$13)*'Indexation Client 2026'!$F$13)*'Indexation Client 2026'!$H$13 -> -24.65792 | Q13: =(('indice Carburant'!K10-'Indexation Client 2026'!$D$13)*'Indexation Client 2026'!$F$13)*'Indexation Client 2026'!$H$13 -> -24.65792 | ... U13: =(('indice Carburant'!O10-'Indexation Client 2026'!$D$13)*'Indexation Client 2026'!$F$13)*'Indexation Client 2026'!$H$13 -> -24.65792
A14: CHRONOPOST CHILLY | B14: 40U76 - AMAZON (CMZ) | C14: CHCMZ | D14: 1.376 | E14: PMM DIREM M-1 | F14: 0.28 | G14: Sur Km | H14: 34 | J14: =(('indice Carburant'!D10-'Indexation Client 2026'!$D$14)*'Indexation Client 2026'!$F$14)*'Indexation Client 2026'!$H$14 -> -0.357952 | K14: =(('indice Carburant'!E10-'Indexation Client 2026'!$D$14)*'Indexation Client 2026'!$F$14)*'Indexation Client 2026'!$H$14 -> -0.13328 | L14: =(('indice Carburant'!F10-'Indexation Client 2026'!$D$14)*'Indexation Client 2026'!$F$14)*'Indexation Client 2026'!$H$14 -> 0.168504 | M14: =(('indice Carburant'!G10-'Indexation Client 2026'!$D$14)*'Indexation Client 2026'!$F$14)*'Indexation Client 2026'!$H$14 -> 3.297728 | N14: =(('indice Carburant'!H10-'Indexation Client 2026'!$D$14)*'Indexation Client 2026'!$F$14)*'Indexation Client 2026'!$H$14 -> -13.09952 | O14: =(('indice Carburant'!I10-'Indexation Client 2026'!$D$14)*'Indexation Client 2026'!$F$14)*'Indexation Client 2026'!$H$14 -> -13.09952 | P14: =(('indice Carburant'!J10-'Indexation Client 2026'!$D$14)*'Indexation Client 2026'!$F$14)*'Indexation Client 2026'!$H$14 -> -13.09952 | Q14: =(('indice Carburant'!K10-'Indexation Client 2026'!$D$14)*'Indexation Client 2026'!$F$14)*'Indexation Client 2026'!$H$14 -> -13.09952 | ... U14: =(('indice Carburant'!O10-'Indexation Client 2026'!$D$14)*'Indexation Client 2026'!$F$14)*'Indexation Client 2026'!$H$14 -> -13.09952
A15: CHRONOPOST CHILLY | B15: 40U88 (Gaz) - CDISCOUNT CMZ | C15: CHCMZ | D15: 1.1431 | E15: PMM DIREM M-1 | F15: 0.28 | G15: Sur Km | H15: 35 | J15: =(('indice Carburant'!D10-'Indexation Client 2026'!$D$15)*'Indexation Client 2026'!$F$15)*'Indexation Client 2026'!$H$15 -> 1.91394 | K15: =(('indice Carburant'!E10-'Indexation Client 2026'!$D$15)*'Indexation Client 2026'!$F$15)*'Indexation Client 2026'!$H$15 -> 2.14522 | L15: =(('indice Carburant'!F10-'Indexation Client 2026'!$D$15)*'Indexation Client 2026'!$F$15)*'Indexation Client 2026'!$H$15 -> 2.45588 | M15: =(('indice Carburant'!G10-'Indexation Client 2026'!$D$15)*'Indexation Client 2026'!$F$15)*'Indexation Client 2026'!$H$15 -> 5.67714 | N15: =(('indice Carburant'!H10-'Indexation Client 2026'!$D$15)*'Indexation Client 2026'!$F$15)*'Indexation Client 2026'!$H$15 -> -11.20238 | O15: =(('indice Carburant'!I10-'Indexation Client 2026'!$D$15)*'Indexation Client 2026'!$F$15)*'Indexation Client 2026'!$H$15 -> -11.20238 | P15: =(('indice Carburant'!J10-'Indexation Client 2026'!$D$15)*'Indexation Client 2026'!$F$15)*'Indexation Client 2026'!$H$15 -> -11.20238 | Q15: =(('indice Carburant'!K10-'Indexation Client 2026'!$D$15)*'Indexation Client 2026'!$F$15)*'Indexation Client 2026'!$H$15 -> -11.20238 | ... U15: =(('indice Carburant'!O10-'Indexation Client 2026'!$D$15)*'Indexation Client 2026'!$F$15)*'Indexation Client 2026'!$H$15 -> -11.20238
A16: CHRONOPOST CHILLY | B16: 40U88 (Gaz) - CDISCOUNT HNI | C16: CHCMZ | D16: 1.1431 | E16: PMM DIREM M-1 | F16: 0.28 | G16: Sur Km | H16: 54 | J16: =(('indice Carburant'!D10-'Indexation Client 2026'!$D$16)*'Indexation Client 2026'!$F$16)*'Indexation Client 2026'!$H$16 -> 2.952936 | K16: =(('indice Carburant'!E10-'Indexation Client 2026'!$D$16)*'Indexation Client 2026'!$F$16)*'Indexation Client 2026'!$H$16 -> 3.309768 | L16: =(('indice Carburant'!F10-'Indexation Client 2026'!$D$16)*'Indexation Client 2026'!$F$16)*'Indexation Client 2026'!$H$16 -> 3.789072 | M16: =(('indice Carburant'!G10-'Indexation Client 2026'!$D$16)*'Indexation Client 2026'!$F$16)*'Indexation Client 2026'!$H$16 -> 8.759016 | N16: =(('indice Carburant'!H10-'Indexation Client 2026'!$D$16)*'Indexation Client 2026'!$F$16)*'Indexation Client 2026'!$H$16 -> -17.283672 | O16: =(('indice Carburant'!I10-'Indexation Client 2026'!$D$16)*'Indexation Client 2026'!$F$16)*'Indexation Client 2026'!$H$16 -> -17.283672 | P16: =(('indice Carburant'!J10-'Indexation Client 2026'!$D$16)*'Indexation Client 2026'!$F$16)*'Indexation Client 2026'!$H$16 -> -17.283672 | Q16: =(('indice Carburant'!K10-'Indexation Client 2026'!$D$16)*'Indexation Client 2026'!$F$16)*'Indexation Client 2026'!$H$16 -> -17.283672 | ... U16: =(('indice Carburant'!O10-'Indexation Client 2026'!$D$16)*'Indexation Client 2026'!$F$16)*'Indexation Client 2026'!$H$16 -> -17.283672
A17: CHRONOPOST CHILLY | B17: 40U96 | C17: CHCMZ | D17: 1.1431 | E17: PMM DIREM M-1 | F17: 0.28 | G17: Sur Km | H17: 4 | J17: =(('indice Carburant'!D10-'Indexation Client 2026'!$D$17)*'Indexation Client 2026'!$F$17)*'Indexation Client 2026'!$H$17 -> 0.218736 | K17: =(('indice Carburant'!E10-'Indexation Client 2026'!$D$17)*'Indexation Client 2026'!$F$17)*'Indexation Client 2026'!$H$17 -> 0.245168 | L17: =(('indice Carburant'!F10-'Indexation Client 2026'!$D$17)*'Indexation Client 2026'!$F$17)*'Indexation Client 2026'!$H$17 -> 0.280672 | M17: =(('indice Carburant'!G10-'Indexation Client 2026'!$D$17)*'Indexation Client 2026'!$F$17)*'Indexation Client 2026'!$H$17 -> 0.648816 | N17: =(('indice Carburant'!H10-'Indexation Client 2026'!$D$17)*'Indexation Client 2026'!$F$17)*'Indexation Client 2026'!$H$17 -> -1.280272 | O17: =(('indice Carburant'!I10-'Indexation Client 2026'!$D$17)*'Indexation Client 2026'!$F$17)*'Indexation Client 2026'!$H$17 -> -1.280272 | P17: =(('indice Carburant'!J10-'Indexation Client 2026'!$D$17)*'Indexation Client 2026'!$F$17)*'Indexation Client 2026'!$H$17 -> -1.280272 | Q17: =(('indice Carburant'!K10-'Indexation Client 2026'!$D$17)*'Indexation Client 2026'!$F$17)*'Indexation Client 2026'!$H$17 -> -1.280272 | ... U17: =(('indice Carburant'!O10-'Indexation Client 2026'!$D$17)*'Indexation Client 2026'!$F$17)*'Indexation Client 2026'!$H$17 -> -1.280272
A18: CHRONOPOST HNI | B18: 23R03 | C18: CHAUL | D18: 1.6994 | E18: PMM DIREM M-1 | F18: 0.28 | G18: Sur Km | H18: 55.6 | J18: =(('indice Carburant'!D10-'Indexation Client 2026'!$D$18)*'Indexation Client 2026'!$F$18)*'Indexation Client 2026'!$H$18 -> -5.620048 | K18: =(('indice Carburant'!E10-'Indexation Client 2026'!$D$18)*'Indexation Client 2026'!$F$18)*'Indexation Client 2026'!$H$18 -> -5.2526432 | L18: =(('indice Carburant'!F10-'Indexation Client 2026'!$D$18)*'Indexation Client 2026'!$F$18)*'Indexation Client 2026'!$H$18 -> -4.7591376 | M18: =(('indice Carburant'!G10-'Indexation Client 2026'!$D$18)*'Indexation Client 2026'!$F$18)*'Indexation Client 2026'!$H$18 -> 0.358064 | N18: =(('indice Carburant'!H10-'Indexation Client 2026'!$D$18)*'Indexation Client 2026'!$F$18)*'Indexation Client 2026'!$H$18 -> -26.456259 | O18: =(('indice Carburant'!I10-'Indexation Client 2026'!$D$18)*'Indexation Client 2026'!$F$18)*'Indexation Client 2026'!$H$18 -> -26.456259 | P18: =(('indice Carburant'!J10-'Indexation Client 2026'!$D$18)*'Indexation Client 2026'!$F$18)*'Indexation Client 2026'!$H$18 -> -26.456259 | Q18: =(('indice Carburant'!K10-'Indexation Client 2026'!$D$18)*'Indexation Client 2026'!$F$18)*'Indexation Client 2026'!$H$18 -> -26.456259 | ... U18: =(('indice Carburant'!O10-'Indexation Client 2026'!$D$18)*'Indexation Client 2026'!$F$18)*'Indexation Client 2026'!$H$18 -> -26.456259
A19: CHRONOPOST HNI | B19: 23R68 | C19: CHAUL | D19: 1.6908 | E19: PMM DIREM M-1 | F19: 0.3 | G19: Sur Km | H19: 169.5 | J19: =(('indice Carburant'!D10-'Indexation Client 2026'!$D$19)*'Indexation Client 2026'!$F$19)*'Indexation Client 2026'!$H$19 -> -17.91954 | K19: =(('indice Carburant'!E10-'Indexation Client 2026'!$D$19)*'Indexation Client 2026'!$F$19)*'Indexation Client 2026'!$H$19 -> -16.71948 | L19: =(('indice Carburant'!F10-'Indexation Client 2026'!$D$19)*'Indexation Client 2026'!$F$19)*'Indexation Client 2026'!$H$19 -> -15.107535 | M19: =(('indice Carburant'!G10-'Indexation Client 2026'!$D$19)*'Indexation Client 2026'!$F$19)*'Indexation Client 2026'!$H$19 -> 1.60686 | N19: =(('indice Carburant'!H10-'Indexation Client 2026'!$D$19)*'Indexation Client 2026'!$F$19)*'Indexation Client 2026'!$H$19 -> -85.97718 | O19: =(('indice Carburant'!I10-'Indexation Client 2026'!$D$19)*'Indexation Client 2026'!$F$19)*'Indexation Client 2026'!$H$19 -> -85.97718 | P19: =(('indice Carburant'!J10-'Indexation Client 2026'!$D$19)*'Indexation Client 2026'!$F$19)*'Indexation Client 2026'!$H$19 -> -85.97718 | Q19: =(('indice Carburant'!K10-'Indexation Client 2026'!$D$19)*'Indexation Client 2026'!$F$19)*'Indexation Client 2026'!$H$19 -> -85.97718 | ... U19: =(('indice Carburant'!O10-'Indexation Client 2026'!$D$19)*'Indexation Client 2026'!$F$19)*'Indexation Client 2026'!$H$19 -> -85.97718
A20: CHRONOPOST HNI | B20: 23R68 | C20: CHAUL | D20: 1.6908 | E20: PMM DIREM M-1 | F20: 0.3 | G20: Sur Km | H20: 56.7 | J20: =(('indice Carburant'!D10-'Indexation Client 2026'!$D$20)*'Indexation Client 2026'!$F$20)*'Indexation Client 2026'!$H$20 -> -5.994324 | K20: =(('indice Carburant'!E10-'Indexation Client 2026'!$D$20)*'Indexation Client 2026'!$F$20)*'Indexation Client 2026'!$H$20 -> -5.592888 | L20: =(('indice Carburant'!F10-'Indexation Client 2026'!$D$20)*'Indexation Client 2026'!$F$20)*'Indexation Client 2026'!$H$20 -> -5.053671 | M20: =(('indice Carburant'!G10-'Indexation Client 2026'!$D$20)*'Indexation Client 2026'!$F$20)*'Indexation Client 2026'!$H$20 -> 0.537516 | N20: =(('indice Carburant'!H10-'Indexation Client 2026'!$D$20)*'Indexation Client 2026'!$F$20)*'Indexation Client 2026'!$H$20 -> -28.760508 | O20: =(('indice Carburant'!I10-'Indexation Client 2026'!$D$20)*'Indexation Client 2026'!$F$20)*'Indexation Client 2026'!$H$20 -> -28.760508 | P20: =(('indice Carburant'!J10-'Indexation Client 2026'!$D$20)*'Indexation Client 2026'!$F$20)*'Indexation Client 2026'!$H$20 -> -28.760508 | Q20: =(('indice Carburant'!K10-'Indexation Client 2026'!$D$20)*'Indexation Client 2026'!$F$20)*'Indexation Client 2026'!$H$20 -> -28.760508 | ... U20: =(('indice Carburant'!O10-'Indexation Client 2026'!$D$20)*'Indexation Client 2026'!$F$20)*'Indexation Client 2026'!$H$20 -> -28.760508
A21: CHRONOPOST HNI | B21: 23R67 | C21: CHAUL | D21: 1.1784 | E21: PMM DIREM M-1 | F21: 0.3 | G21: Sur Km | H21: 49.4 | J21: =(('indice Carburant'!D10-'Indexation Client 2026'!$D$21)*'Indexation Client 2026'!$F$21)*'Indexation Client 2026'!$H$21 -> 2.3712 | K21: =(('indice Carburant'!E10-'Indexation Client 2026'!$D$21)*'Indexation Client 2026'!$F$21)*'Indexation Client 2026'!$H$21 -> 2.720952 | L21: =(('indice Carburant'!F10-'Indexation Client 2026'!$D$21)*'Indexation Client 2026'!$F$21)*'Indexation Client 2026'!$H$21 -> 3.190746 | M21: =(('indice Carburant'!G10-'Indexation Client 2026'!$D$21)*'Indexation Client 2026'!$F$21)*'Indexation Client 2026'!$H$21 -> 8.06208 | N21: =(('indice Carburant'!H10-'Indexation Client 2026'!$D$21)*'Indexation Client 2026'!$F$21)*'Indexation Client 2026'!$H$21 -> -17.463888 | O21: =(('indice Carburant'!I10-'Indexation Client 2026'!$D$21)*'Indexation Client 2026'!$F$21)*'Indexation Client 2026'!$H$21 -> -17.463888 | P21: =(('indice Carburant'!J10-'Indexation Client 2026'!$D$21)*'Indexation Client 2026'!$F$21)*'Indexation Client 2026'!$H$21 -> -17.463888 | Q21: =(('indice Carburant'!K10-'Indexation Client 2026'!$D$21)*'Indexation Client 2026'!$F$21)*'Indexation Client 2026'!$H$21 -> -17.463888 | ... U21: =(('indice Carburant'!O10-'Indexation Client 2026'!$D$21)*'Indexation Client 2026'!$F$21)*'Indexation Client 2026'!$H$21 -> -17.463888
A22: CHRONOPOST RESEAU | B22: SWAP GAZ | C22: CHRON | D22: 0.94 | E22: CNR GNV M-1/100 | F22: 0.29 | G22: Sur Km | J22: =((('indice Carburant'!D13/100)-'Indexation Client 2026'!$D$22)*'Indexation Client 2026'!$F$22) -> 0.195547 | K22: =((('indice Carburant'!E13/100)-'Indexation Client 2026'!$D$22)*'Indexation Client 2026'!$F$22) -> 0.190269 | L22: =((('indice Carburant'!F13/100)-'Indexation Client 2026'!$D$22)*'Indexation Client 2026'!$F$22) -> 0.242672 | M22: =((('indice Carburant'!G13/100)-'Indexation Client 2026'!$D$22)*'Indexation Client 2026'!$F$22) -> -0.2726 | N22: =((('indice Carburant'!H13/100)-'Indexation Client 2026'!$D$22)*'Indexation Client 2026'!$F$22) -> -0.2726 | O22: =((('indice Carburant'!I13/100)-'Indexation Client 2026'!$D$22)*'Indexation Client 2026'!$F$22) -> -0.2726 | P22: =((('indice Carburant'!J13/100)-'Indexation Client 2026'!$D$22)*'Indexation Client 2026'!$F$22) -> -0.2726 | Q22: =((('indice Carburant'!K13/100)-'Indexation Client 2026'!$D$22)*'Indexation Client 2026'!$F$22) -> -0.2726 | ... U22: =((('indice Carburant'!O13/100)-'Indexation Client 2026'!$D$22)*'Indexation Client 2026'!$F$22) -> -0.2726
A23: CHRONOPOST RESEAU | B23: SWAP GO | C23: CHRON | D23: 0.8318 | E23: PMM DIREM M-1 | F23: 0.29 | G23: Sur Km | J23: =(('indice Carburant'!D10-'Indexation Client 2026'!$D$23)*'Indexation Client 2026'!$F$23) -> 0.146914 | K23: =(('indice Carburant'!E10-'Indexation Client 2026'!$D$23)*'Indexation Client 2026'!$F$23) -> 0.153758 | L23: =(('indice Carburant'!F10-'Indexation Client 2026'!$D$23)*'Indexation Client 2026'!$F$23) -> 0.162951 | M23: =(('indice Carburant'!G10-'Indexation Client 2026'!$D$23)*'Indexation Client 2026'!$F$23) -> 0.258274 | N23: =(('indice Carburant'!H10-'Indexation Client 2026'!$D$23)*'Indexation Client 2026'!$F$23) -> -0.241222 | O23: =(('indice Carburant'!I10-'Indexation Client 2026'!$D$23)*'Indexation Client 2026'!$F$23) -> -0.241222 | P23: =(('indice Carburant'!J10-'Indexation Client 2026'!$D$23)*'Indexation Client 2026'!$F$23) -> -0.241222 | Q23: =(('indice Carburant'!K10-'Indexation Client 2026'!$D$23)*'Indexation Client 2026'!$F$23) -> -0.241222 | ... U23: =(('indice Carburant'!O10-'Indexation Client 2026'!$D$23)*'Indexation Client 2026'!$F$23) -> -0.241222
A24: CHRONOPOST RESEAU | B24: SPL GAZ | C24: CHRON | D24: 0.94 | E24: CNR GNV M-1/100 | F24: 0.26 | G24: Sur Km | J24: =((('indice Carburant'!D13/100)-'Indexation Client 2026'!$D$24)*'Indexation Client 2026'!$F$24) -> 0.175318 | K24: =((('indice Carburant'!E13/100)-'Indexation Client 2026'!$D$24)*'Indexation Client 2026'!$F$24) -> 0.170586 | L24: =((('indice Carburant'!F13/100)-'Indexation Client 2026'!$D$24)*'Indexation Client 2026'!$F$24) -> 0.217568 | M24: =((('indice Carburant'!G13/100)-'Indexation Client 2026'!$D$24)*'Indexation Client 2026'!$F$24) -> -0.2444 | N24: =((('indice Carburant'!H13/100)-'Indexation Client 2026'!$D$24)*'Indexation Client 2026'!$F$24) -> -0.2444 | O24: =((('indice Carburant'!I13/100)-'Indexation Client 2026'!$D$24)*'Indexation Client 2026'!$F$24) -> -0.2444 | P24: =((('indice Carburant'!J13/100)-'Indexation Client 2026'!$D$24)*'Indexation Client 2026'!$F$24) -> -0.2444 | Q24: =((('indice Carburant'!K13/100)-'Indexation Client 2026'!$D$24)*'Indexation Client 2026'!$F$24) -> -0.2444 | ... U24: =((('indice Carburant'!O13/100)-'Indexation Client 2026'!$D$24)*'Indexation Client 2026'!$F$24) -> -0.2444
A25: CHRONOPOST RESEAU | B25: VL GO | C25: CHRON | D25: 0.8318 | E25: PMM DIREM M-1 | F25: 0.15 | G25: Sur Km | J25: =(('indice Carburant'!D10-'Indexation Client 2026'!$D$25)*'Indexation Client 2026'!$F$25) -> 0.07599 | K25: =(('indice Carburant'!E10-'Indexation Client 2026'!$D$25)*'Indexation Client 2026'!$F$25) -> 0.07953 | L25: =(('indice Carburant'!F10-'Indexation Client 2026'!$D$25)*'Indexation Client 2026'!$F$25) -> 0.084285 | M25: =(('indice Carburant'!G10-'Indexation Client 2026'!$D$25)*'Indexation Client 2026'!$F$25) -> 0.13359 | N25: =(('indice Carburant'!H10-'Indexation Client 2026'!$D$25)*'Indexation Client 2026'!$F$25) -> -0.12477 | O25: =(('indice Carburant'!I10-'Indexation Client 2026'!$D$25)*'Indexation Client 2026'!$F$25) -> -0.12477 | P25: =(('indice Carburant'!J10-'Indexation Client 2026'!$D$25)*'Indexation Client 2026'!$F$25) -> -0.12477 | Q25: =(('indice Carburant'!K10-'Indexation Client 2026'!$D$25)*'Indexation Client 2026'!$F$25) -> -0.12477 | ... U25: =(('indice Carburant'!O10-'Indexation Client 2026'!$D$25)*'Indexation Client 2026'!$F$25) -> -0.12477
A26: CHRONOPOST RESEAU | B26: SPL GO | C26: CHRON | D26: 0.8318 | E26: PMM DIREM M-1 | F26: 0.26 | G26: Sur Km | J26: =(('indice Carburant'!D10-'Indexation Client 2026'!$D$26)*'Indexation Client 2026'!$F$26) -> 0.131716 | K26: =(('indice Carburant'!E10-'Indexation Client 2026'!$D$26)*'Indexation Client 2026'!$F$26) -> 0.137852 | L26: =(('indice Carburant'!F10-'Indexation Client 2026'!$D$26)*'Indexation Client 2026'!$F$26) -> 0.146094 | M26: =(('indice Carburant'!G10-'Indexation Client 2026'!$D$26)*'Indexation Client 2026'!$F$26) -> 0.231556 | N26: =(('indice Carburant'!H10-'Indexation Client 2026'!$D$26)*'Indexation Client 2026'!$F$26) -> -0.216268 | O26: =(('indice Carburant'!I10-'Indexation Client 2026'!$D$26)*'Indexation Client 2026'!$F$26) -> -0.216268 | P26: =(('indice Carburant'!J10-'Indexation Client 2026'!$D$26)*'Indexation Client 2026'!$F$26) -> -0.216268 | Q26: =(('indice Carburant'!K10-'Indexation Client 2026'!$D$26)*'Indexation Client 2026'!$F$26) -> -0.216268 | ... U26: =(('indice Carburant'!O10-'Indexation Client 2026'!$D$26)*'Indexation Client 2026'!$F$26) -> -0.216268
A27: CHRONOPOST ROISSY | B27: LRCDGORY01 | C27: CHROI | D27: 1.3384 | E27: PMM DIREM M-1 | F27: 0.26 | G27: Sur Km | H27: 44 | J27: =(('indice Carburant'!D10-'Indexation Client 2026'!$D$27)*'Indexation Client 2026'!$F$27)*'Indexation Client 2026'!$H$27 -> 0 | K27: =(('indice Carburant'!E10-'Indexation Client 2026'!$D$27)*'Indexation Client 2026'!$F$27)*'Indexation Client 2026'!$H$27 -> 0.269984 | L27: =(('indice Carburant'!F10-'Indexation Client 2026'!$D$27)*'Indexation Client 2026'!$F$27)*'Indexation Client 2026'!$H$27 -> 0.632632 | M27: =(('indice Carburant'!G10-'Indexation Client 2026'!$D$27)*'Indexation Client 2026'!$F$27)*'Indexation Client 2026'!$H$27 -> 4.39296 | N27: =(('indice Carburant'!H10-'Indexation Client 2026'!$D$27)*'Indexation Client 2026'!$F$27)*'Indexation Client 2026'!$H$27 -> -15.311296 | O27: =(('indice Carburant'!I10-'Indexation Client 2026'!$D$27)*'Indexation Client 2026'!$F$27)*'Indexation Client 2026'!$H$27 -> -15.311296 | P27: =(('indice Carburant'!J10-'Indexation Client 2026'!$D$27)*'Indexation Client 2026'!$F$27)*'Indexation Client 2026'!$H$27 -> -15.311296 | Q27: =(('indice Carburant'!K10-'Indexation Client 2026'!$D$27)*'Indexation Client 2026'!$F$27)*'Indexation Client 2026'!$H$27 -> -15.311296 | ... U27: =(('indice Carburant'!O10-'Indexation Client 2026'!$D$27)*'Indexation Client 2026'!$F$27)*'Indexation Client 2026'!$H$27 -> -15.311296
A28: CHRONOPOST ROISSY | B28: LRCDGORY02 | C28: CHROI | D28: 1.3384 | E28: PMM DIREM M-1 | F28: 0.26 | G28: Sur Km | H28: 44 | J28: =(('indice Carburant'!D10-'Indexation Client 2026'!$D$28)*'Indexation Client 2026'!$F$28)*'Indexation Client 2026'!$H$28 -> 0 | K28: =(('indice Carburant'!E10-'Indexation Client 2026'!$D$28)*'Indexation Client 2026'!$F$28)*'Indexation Client 2026'!$H$28 -> 0.269984 | L28: =(('indice Carburant'!F10-'Indexation Client 2026'!$D$28)*'Indexation Client 2026'!$F$28)*'Indexation Client 2026'!$H$28 -> 0.632632 | M28: =(('indice Carburant'!G10-'Indexation Client 2026'!$D$28)*'Indexation Client 2026'!$F$28)*'Indexation Client 2026'!$H$28 -> 4.39296 | N28: =(('indice Carburant'!H10-'Indexation Client 2026'!$D$28)*'Indexation Client 2026'!$F$28)*'Indexation Client 2026'!$H$28 -> -15.311296 | O28: =(('indice Carburant'!I10-'Indexation Client 2026'!$D$28)*'Indexation Client 2026'!$F$28)*'Indexation Client 2026'!$H$28 -> -15.311296 | P28: =(('indice Carburant'!J10-'Indexation Client 2026'!$D$28)*'Indexation Client 2026'!$F$28)*'Indexation Client 2026'!$H$28 -> -15.311296 | Q28: =(('indice Carburant'!K10-'Indexation Client 2026'!$D$28)*'Indexation Client 2026'!$F$28)*'Indexation Client 2026'!$H$28 -> -15.311296 | ... U28: =(('indice Carburant'!O10-'Indexation Client 2026'!$D$28)*'Indexation Client 2026'!$F$28)*'Indexation Client 2026'!$H$28 -> -15.311296
A29: COLISSIMO | B29: CTRT 202213366 | C29: CSPN | D29: PARC
A30: COLISSIMO | B30: GEN202212891SLOT04 | C30: CSPN | D30: 180.42 | E30: CNR GO PRO M-1 | F30: 0.1398 | G30: Variation TK | H30: 3.4 | J30: =((('indice Carburant'!D6/'Indexation Client 2026'!$D$30)-1)*'Indexation Client 2026'!$F$30)*'Indexation Client 2026'!$H$30+$H$30 -> 3.402898 | K30: =((('indice Carburant'!E6/'Indexation Client 2026'!$D$30)-1)*'Indexation Client 2026'!$F$30)*'Indexation Client 2026'!$H$30+$H$30 -> 3.4190739 | L30: =((('indice Carburant'!F6/'Indexation Client 2026'!$D$30)-1)*'Indexation Client 2026'!$F$30)*'Indexation Client 2026'!$H$30+$H$30 -> 3.434038 | M30: =((('indice Carburant'!G6/'Indexation Client 2026'!$D$30)-1)*'Indexation Client 2026'!$F$30)*'Indexation Client 2026'!$H$30+$H$30 -> 3.5782516 | N30: =((('indice Carburant'!H6/'Indexation Client 2026'!$D$30)-1)*'Indexation Client 2026'!$F$30)*'Indexation Client 2026'!$H$30+$H$30 -> 2.92468 | O30: =((('indice Carburant'!I6/'Indexation Client 2026'!$D$30)-1)*'Indexation Client 2026'!$F$30)*'Indexation Client 2026'!$H$30+$H$30 -> 2.92468 | P30: =((('indice Carburant'!J6/'Indexation Client 2026'!$D$30)-1)*'Indexation Client 2026'!$F$30)*'Indexation Client 2026'!$H$30+$H$30 -> 2.92468 | Q30: =((('indice Carburant'!K6/'Indexation Client 2026'!$D$30)-1)*'Indexation Client 2026'!$F$30)*'Indexation Client 2026'!$H$30+$H$30 -> 2.92468 | ... U30: =((('indice Carburant'!O6/'Indexation Client 2026'!$D$30)-1)*'Indexation Client 2026'!$F$30)*'Indexation Client 2026'!$H$30+$H$30 -> 2.92468
A31: COLISSIMO | B31: IDFLTHCGENC9595 | C31: CSPN | D31: 273.99 | E31: CNR GO PRO M-1 | F31: 0.2137 | G31: Variation TK | H31: 2.5021 | J31: =((('indice Carburant'!D6/'Indexation Client 2026'!$D$31)-1)*'Indexation Client 2026'!$F$31)*'Indexation Client 2026'!$H$31+$H$31 -> 2.3216423 | K31: =((('indice Carburant'!E6/'Indexation Client 2026'!$D$31)-1)*'Indexation Client 2026'!$F$31)*'Indexation Client 2026'!$H$31+$H$31 -> 2.3336247 | L31: =((('indice Carburant'!F6/'Indexation Client 2026'!$D$31)-1)*'Indexation Client 2026'!$F$31)*'Indexation Client 2026'!$H$31+$H$31 -> 2.3447094 | M31: =((('indice Carburant'!G6/'Indexation Client 2026'!$D$31)-1)*'Indexation Client 2026'!$F$31)*'Indexation Client 2026'!$H$31+$H$31 -> 2.4515359 | N31: =((('indice Carburant'!H6/'Indexation Client 2026'!$D$31)-1)*'Indexation Client 2026'!$F$31)*'Indexation Client 2026'!$H$31+$H$31 -> 1.9674012 | O31: =((('indice Carburant'!I6/'Indexation Client 2026'!$D$31)-1)*'Indexation Client 2026'!$F$31)*'Indexation Client 2026'!$H$31+$H$31 -> 1.9674012 | P31: =((('indice Carburant'!J6/'Indexation Client 2026'!$D$31)-1)*'Indexation Client 2026'!$F$31)*'Indexation Client 2026'!$H$31+$H$31 -> 1.9674012 | Q31: =((('indice Carburant'!K6/'Indexation Client 2026'!$D$31)-1)*'Indexation Client 2026'!$F$31)*'Indexation Client 2026'!$H$31+$H$31 -> 1.9674012 | ... U31: =((('indice Carburant'!O6/'Indexation Client 2026'!$D$31)-1)*'Indexation Client 2026'!$F$31)*'Indexation Client 2026'!$H$31+$H$31 -> 1.9674012
A32: COLISSIMO | B32: IDFN-DOT-00A-CM | C32: CSPN | D32: 182.15 | E32: CNR GNV M-1 | F32: 0.1684 | G32: Variation TK | H32: 2.413 | J32: =((('indice Carburant'!D13/'Indexation Client 2026'!$D$32)-1)*'Indexation Client 2026'!$F$32)*'Indexation Client 2026'!$H$32+$H$32 -> 2.3667768 | K32: =((('indice Carburant'!E13/'Indexation Client 2026'!$D$32)-1)*'Indexation Client 2026'!$F$32)*'Indexation Client 2026'!$H$32+$H$32 -> 2.3627167 | L32: =((('indice Carburant'!F13/'Indexation Client 2026'!$D$32)-1)*'Indexation Client 2026'!$F$32)*'Indexation Client 2026'!$H$32+$H$32 -> 2.4030281 | M32: =((('indice Carburant'!G13/'Indexation Client 2026'!$D$32)-1)*'Indexation Client 2026'!$F$32)*'Indexation Client 2026'!$H$32+$H$32 -> 2.0066508 | N32: =((('indice Carburant'!H13/'Indexation Client 2026'!$D$32)-1)*'Indexation Client 2026'!$F$32)*'Indexation Client 2026'!$H$32+$H$32 -> 2.0066508 | O32: =((('indice Carburant'!I13/'Indexation Client 2026'!$D$32)-1)*'Indexation Client 2026'!$F$32)*'Indexation Client 2026'!$H$32+$H$32 -> 2.0066508 | P32: =((('indice Carburant'!J13/'Indexation Client 2026'!$D$32)-1)*'Indexation Client 2026'!$F$32)*'Indexation Client 2026'!$H$32+$H$32 -> 2.0066508 | Q32: =((('indice Carburant'!K13/'Indexation Client 2026'!$D$32)-1)*'Indexation Client 2026'!$F$32)*'Indexation Client 2026'!$H$32+$H$32 -> 2.0066508 | ... U32: =((('indice Carburant'!O13/'Indexation Client 2026'!$D$32)-1)*'Indexation Client 2026'!$F$32)*'Indexation Client 2026'!$H$32+$H$32 -> 2.0066508
A33: COLISSIMO | B33: IDFN-LTH-004-CM | C33: CSPN | D33: 182.15 | E33: CNR GNV M-1 | F33: 0.0983 | G33: Variation TK | H33: 4.135 | J33: =((('indice Carburant'!D13/'Indexation Client 2026'!$D$33)-1)*'Indexation Client 2026'!$F$33)*'Indexation Client 2026'!$H$33+$H$33 -> 4.088763 | K33: =((('indice Carburant'!E13/'Indexation Client 2026'!$D$33)-1)*'Indexation Client 2026'!$F$33)*'Indexation Client 2026'!$H$33+$H$33 -> 4.0847016 | L33: =((('indice Carburant'!F13/'Indexation Client 2026'!$D$33)-1)*'Indexation Client 2026'!$F$33)*'Indexation Client 2026'!$H$33+$H$33 -> 4.1250251 | M33: =((('indice Carburant'!G13/'Indexation Client 2026'!$D$33)-1)*'Indexation Client 2026'!$F$33)*'Indexation Client 2026'!$H$33+$H$33 -> 3.7285295 | N33: =((('indice Carburant'!H13/'Indexation Client 2026'!$D$33)-1)*'Indexation Client 2026'!$F$33)*'Indexation Client 2026'!$H$33+$H$33 -> 3.7285295 | O33: =((('indice Carburant'!I13/'Indexation Client 2026'!$D$33)-1)*'Indexation Client 2026'!$F$33)*'Indexation Client 2026'!$H$33+$H$33 -> 3.7285295 | P33: =((('indice Carburant'!J13/'Indexation Client 2026'!$D$33)-1)*'Indexation Client 2026'!$F$33)*'Indexation Client 2026'!$H$33+$H$33 -> 3.7285295 | Q33: =((('indice Carburant'!K13/'Indexation Client 2026'!$D$33)-1)*'Indexation Client 2026'!$F$33)*'Indexation Client 2026'!$H$33+$H$33 -> 3.7285295 | ... U33: =((('indice Carburant'!O13/'Indexation Client 2026'!$D$33)-1)*'Indexation Client 2026'!$F$33)*'Indexation Client 2026'!$H$33+$H$33 -> 3.7285295
A34: COLISSIMO | B34: IDFN-LTH-007-CM | C34: CSPN | D34: 182.15 | E34: CNR GNV M-1 | F34: 0.169 | G34: Variation TK | H34: 2.2548 | J34: =((('indice Carburant'!D13/'Indexation Client 2026'!$D$34)-1)*'Indexation Client 2026'!$F$34)*'Indexation Client 2026'!$H$34+$H$34 -> 2.2114534 | K34: =((('indice Carburant'!E13/'Indexation Client 2026'!$D$34)-1)*'Indexation Client 2026'!$F$34)*'Indexation Client 2026'!$H$34+$H$34 -> 2.2076459 | L34: =((('indice Carburant'!F13/'Indexation Client 2026'!$D$34)-1)*'Indexation Client 2026'!$F$34)*'Indexation Client 2026'!$H$34+$H$34 -> 2.2454487 | M34: =((('indice Carburant'!G13/'Indexation Client 2026'!$D$34)-1)*'Indexation Client 2026'!$F$34)*'Indexation Client 2026'!$H$34+$H$34 -> 1.8737388 | N34: =((('indice Carburant'!H13/'Indexation Client 2026'!$D$34)-1)*'Indexation Client 2026'!$F$34)*'Indexation Client 2026'!$H$34+$H$34 -> 1.8737388 | O34: =((('indice Carburant'!I13/'Indexation Client 2026'!$D$34)-1)*'Indexation Client 2026'!$F$34)*'Indexation Client 2026'!$H$34+$H$34 -> 1.8737388 | P34: =((('indice Carburant'!J13/'Indexation Client 2026'!$D$34)-1)*'Indexation Client 2026'!$F$34)*'Indexation Client 2026'!$H$34+$H$34 -> 1.8737388 | Q34: =((('indice Carburant'!K13/'Indexation Client 2026'!$D$34)-1)*'Indexation Client 2026'!$F$34)*'Indexation Client 2026'!$H$34+$H$34 -> 1.8737388 | ... U34: =((('indice Carburant'!O13/'Indexation Client 2026'!$D$34)-1)*'Indexation Client 2026'!$F$34)*'Indexation Client 2026'!$H$34+$H$34 -> 1.8737388
A35: COLISSIMO | B35: IDFN-LTH-009-S33 | C35: CSPN | D35: 182.15 | E35: CNR GNV M-1 | F35: 0.1942 | G35: Variation TK | H35: 2.0315 | J35: =((('indice Carburant'!D13/'Indexation Client 2026'!$D$35)-1)*'Indexation Client 2026'!$F$35)*'Indexation Client 2026'!$H$35+$H$35 -> 1.9866227 | K35: =((('indice Carburant'!E13/'Indexation Client 2026'!$D$35)-1)*'Indexation Client 2026'!$F$35)*'Indexation Client 2026'!$H$35+$H$35 -> 1.9826808 | L35: =((('indice Carburant'!F13/'Indexation Client 2026'!$D$35)-1)*'Indexation Client 2026'!$F$35)*'Indexation Client 2026'!$H$35+$H$35 -> 2.0218185 | M35: =((('indice Carburant'!G13/'Indexation Client 2026'!$D$35)-1)*'Indexation Client 2026'!$F$35)*'Indexation Client 2026'!$H$35+$H$35 -> 1.6369827 | N35: =((('indice Carburant'!H13/'Indexation Client 2026'!$D$35)-1)*'Indexation Client 2026'!$F$35)*'Indexation Client 2026'!$H$35+$H$35 -> 1.6369827 | O35: =((('indice Carburant'!I13/'Indexation Client 2026'!$D$35)-1)*'Indexation Client 2026'!$F$35)*'Indexation Client 2026'!$H$35+$H$35 -> 1.6369827 | P35: =((('indice Carburant'!J13/'Indexation Client 2026'!$D$35)-1)*'Indexation Client 2026'!$F$35)*'Indexation Client 2026'!$H$35+$H$35 -> 1.6369827 | Q35: =((('indice Carburant'!K13/'Indexation Client 2026'!$D$35)-1)*'Indexation Client 2026'!$F$35)*'Indexation Client 2026'!$H$35+$H$35 -> 1.6369827 | ... U35: =((('indice Carburant'!O13/'Indexation Client 2026'!$D$35)-1)*'Indexation Client 2026'!$F$35)*'Indexation Client 2026'!$H$35+$H$35 -> 1.6369827
A36: COLISSIMO | B36: IDFN-LTH-011-CM | C36: CSPN | D36: 182.15 | E36: CNR GNV M-1 | F36: 0.238 | G36: Variation TK | H36: 1.7074 | J36: =((('indice Carburant'!D13/'Indexation Client 2026'!$D$36)-1)*'Indexation Client 2026'!$F$36)*'Indexation Client 2026'!$H$36+$H$36 -> 1.6611754 | K36: =((('indice Carburant'!E13/'Indexation Client 2026'!$D$36)-1)*'Indexation Client 2026'!$F$36)*'Indexation Client 2026'!$H$36+$H$36 -> 1.6571152 | L36: =((('indice Carburant'!F13/'Indexation Client 2026'!$D$36)-1)*'Indexation Client 2026'!$F$36)*'Indexation Client 2026'!$H$36+$H$36 -> 1.6974278 | M36: =((('indice Carburant'!G13/'Indexation Client 2026'!$D$36)-1)*'Indexation Client 2026'!$F$36)*'Indexation Client 2026'!$H$36+$H$36 -> 1.3010388 | N36: =((('indice Carburant'!H13/'Indexation Client 2026'!$D$36)-1)*'Indexation Client 2026'!$F$36)*'Indexation Client 2026'!$H$36+$H$36 -> 1.3010388 | O36: =((('indice Carburant'!I13/'Indexation Client 2026'!$D$36)-1)*'Indexation Client 2026'!$F$36)*'Indexation Client 2026'!$H$36+$H$36 -> 1.3010388 | P36: =((('indice Carburant'!J13/'Indexation Client 2026'!$D$36)-1)*'Indexation Client 2026'!$F$36)*'Indexation Client 2026'!$H$36+$H$36 -> 1.3010388 | Q36: =((('indice Carburant'!K13/'Indexation Client 2026'!$D$36)-1)*'Indexation Client 2026'!$F$36)*'Indexation Client 2026'!$H$36+$H$36 -> 1.3010388 | ... U36: =((('indice Carburant'!O13/'Indexation Client 2026'!$D$36)-1)*'Indexation Client 2026'!$F$36)*'Indexation Client 2026'!$H$36+$H$36 -> 1.3010388
A37: COLISSIMO | B37: IDFN-LTH-014-CM | C37: CSPN | D37: 182.15 | E37: CNR GNV M-1 | F37: 0.2003 | G37: Variation TK | H37: 2.47 | J37: =((('indice Carburant'!D13/'Indexation Client 2026'!$D$37)-1)*'Indexation Client 2026'!$F$37)*'Indexation Client 2026'!$H$37+$H$37 -> 2.413722 | K37: =((('indice Carburant'!E13/'Indexation Client 2026'!$D$37)-1)*'Indexation Client 2026'!$F$37)*'Indexation Client 2026'!$H$37+$H$37 -> 2.4087787 | L37: =((('indice Carburant'!F13/'Indexation Client 2026'!$D$37)-1)*'Indexation Client 2026'!$F$37)*'Indexation Client 2026'!$H$37+$H$37 -> 2.4578589 | M37: =((('indice Carburant'!G13/'Indexation Client 2026'!$D$37)-1)*'Indexation Client 2026'!$F$37)*'Indexation Client 2026'!$H$37+$H$37 -> 1.975259 | N37: =((('indice Carburant'!H13/'Indexation Client 2026'!$D$37)-1)*'Indexation Client 2026'!$F$37)*'Indexation Client 2026'!$H$37+$H$37 -> 1.975259 | O37: =((('indice Carburant'!I13/'Indexation Client 2026'!$D$37)-1)*'Indexation Client 2026'!$F$37)*'Indexation Client 2026'!$H$37+$H$37 -> 1.975259 | P37: =((('indice Carburant'!J13/'Indexation Client 2026'!$D$37)-1)*'Indexation Client 2026'!$F$37)*'Indexation Client 2026'!$H$37+$H$37 -> 1.975259 | Q37: =((('indice Carburant'!K13/'Indexation Client 2026'!$D$37)-1)*'Indexation Client 2026'!$F$37)*'Indexation Client 2026'!$H$37+$H$37 -> 1.975259 | ... U37: =((('indice Carburant'!O13/'Indexation Client 2026'!$D$37)-1)*'Indexation Client 2026'!$F$37)*'Indexation Client 2026'!$H$37+$H$37 -> 1.975259
A38: COLISSIMO | B38: IDFN-LTH-016-S33 | C38: CSPN | D38: 153.94 | E38: CNR GNV M-1 | F38: 0.1376 | G38: Variation TK | H38: 4.4842 | J38: =((('indice Carburant'!D13/'Indexation Client 2026'!$D$38)-1)*'Indexation Client 2026'!$F$38)*'Indexation Client 2026'!$H$38+$H$38 -> 4.5142216 | K38: =((('indice Carburant'!E13/'Indexation Client 2026'!$D$38)-1)*'Indexation Client 2026'!$F$38)*'Indexation Client 2026'!$H$38+$H$38 -> 4.5069266 | L38: =((('indice Carburant'!F13/'Indexation Client 2026'!$D$38)-1)*'Indexation Client 2026'!$F$38)*'Indexation Client 2026'!$H$38+$H$38 -> 4.5793552 | M38: =((('indice Carburant'!G13/'Indexation Client 2026'!$D$38)-1)*'Indexation Client 2026'!$F$38)*'Indexation Client 2026'!$H$38+$H$38 -> 3.8671741 | N38: =((('indice Carburant'!H13/'Indexation Client 2026'!$D$38)-1)*'Indexation Client 2026'!$F$38)*'Indexation Client 2026'!$H$38+$H$38 -> 3.8671741 | O38: =((('indice Carburant'!I13/'Indexation Client 2026'!$D$38)-1)*'Indexation Client 2026'!$F$38)*'Indexation Client 2026'!$H$38+$H$38 -> 3.8671741 | P38: =((('indice Carburant'!J13/'Indexation Client 2026'!$D$38)-1)*'Indexation Client 2026'!$F$38)*'Indexation Client 2026'!$H$38+$H$38 -> 3.8671741 | Q38: =((('indice Carburant'!K13/'Indexation Client 2026'!$D$38)-1)*'Indexation Client 2026'!$F$38)*'Indexation Client 2026'!$H$38+$H$38 -> 3.8671741 | ... U38: =((('indice Carburant'!O13/'Indexation Client 2026'!$D$38)-1)*'Indexation Client 2026'!$F$38)*'Indexation Client 2026'!$H$38+$H$38 -> 3.8671741
A39: COLISSIMO | B39: IDFN-LTH-017-S33 | C39: CSPN | D39: 153.94 | E39: CNR GNV M-1 | F39: 0.1564 | G39: Variation TK | H39: 2.4922 | J39: =((('indice Carburant'!D13/'Indexation Client 2026'!$D$39)-1)*'Indexation Client 2026'!$F$39)*'Indexation Client 2026'!$H$39+$H$39 -> 2.5111649 | K39: =((('indice Carburant'!E13/'Indexation Client 2026'!$D$39)-1)*'Indexation Client 2026'!$F$39)*'Indexation Client 2026'!$H$39+$H$39 -> 2.5065566 | L39: =((('indice Carburant'!F13/'Indexation Client 2026'!$D$39)-1)*'Indexation Client 2026'!$F$39)*'Indexation Client 2026'!$H$39+$H$39 -> 2.5523103 | M39: =((('indice Carburant'!G13/'Indexation Client 2026'!$D$39)-1)*'Indexation Client 2026'!$F$39)*'Indexation Client 2026'!$H$39+$H$39 -> 2.1024199 | N39: =((('indice Carburant'!H13/'Indexation Client 2026'!$D$39)-1)*'Indexation Client 2026'!$F$39)*'Indexation Client 2026'!$H$39+$H$39 -> 2.1024199 | O39: =((('indice Carburant'!I13/'Indexation Client 2026'!$D$39)-1)*'Indexation Client 2026'!$F$39)*'Indexation Client 2026'!$H$39+$H$39 -> 2.1024199 | P39: =((('indice Carburant'!J13/'Indexation Client 2026'!$D$39)-1)*'Indexation Client 2026'!$F$39)*'Indexation Client 2026'!$H$39+$H$39 -> 2.1024199 | Q39: =((('indice Carburant'!K13/'Indexation Client 2026'!$D$39)-1)*'Indexation Client 2026'!$F$39)*'Indexation Client 2026'!$H$39+$H$39 -> 2.1024199 | ... U39: =((('indice Carburant'!O13/'Indexation Client 2026'!$D$39)-1)*'Indexation Client 2026'!$F$39)*'Indexation Client 2026'!$H$39+$H$39 -> 2.1024199
A40: COLISSIMO | B40: IDFN-LTH-081-CM | C40: CSPN | D40: 153.94 | E40: CNR GNV M-1 | F40: 0.1557 | G40: Variation TK | H40: 2.3944 | J40: =((('indice Carburant'!D13/'Indexation Client 2026'!$D$40)-1)*'Indexation Client 2026'!$F$40)*'Indexation Client 2026'!$H$40+$H$40 -> 2.4125391 | K40: =((('indice Carburant'!E13/'Indexation Client 2026'!$D$40)-1)*'Indexation Client 2026'!$F$40)*'Indexation Client 2026'!$H$40+$H$40 -> 2.4081315 | L40: =((('indice Carburant'!F13/'Indexation Client 2026'!$D$40)-1)*'Indexation Client 2026'!$F$40)*'Indexation Client 2026'!$H$40+$H$40 -> 2.4518929 | M40: =((('indice Carburant'!G13/'Indexation Client 2026'!$D$40)-1)*'Indexation Client 2026'!$F$40)*'Indexation Client 2026'!$H$40+$H$40 -> 2.0215919 | N40: =((('indice Carburant'!H13/'Indexation Client 2026'!$D$40)-1)*'Indexation Client 2026'!$F$40)*'Indexation Client 2026'!$H$40+$H$40 -> 2.0215919 | O40: =((('indice Carburant'!I13/'Indexation Client 2026'!$D$40)-1)*'Indexation Client 2026'!$F$40)*'Indexation Client 2026'!$H$40+$H$40 -> 2.0215919 | P40: =((('indice Carburant'!J13/'Indexation Client 2026'!$D$40)-1)*'Indexation Client 2026'!$F$40)*'Indexation Client 2026'!$H$40+$H$40 -> 2.0215919 | Q40: =((('indice Carburant'!K13/'Indexation Client 2026'!$D$40)-1)*'Indexation Client 2026'!$F$40)*'Indexation Client 2026'!$H$40+$H$40 -> 2.0215919 | ... U40: =((('indice Carburant'!O13/'Indexation Client 2026'!$D$40)-1)*'Indexation Client 2026'!$F$40)*'Indexation Client 2026'!$H$40+$H$40 -> 2.0215919
A41: COLISSIMO | B41: IDFS-MJD-88-CM | C41: CSPN | D41: 153.94 | E41: CNR GNV M-1 | F41: 0.2347 | G41: Variation TK | H41: 1.5889 | J41: =((('indice Carburant'!D13/'Indexation Client 2026'!$D$41)-1)*'Indexation Client 2026'!$F$41)*'Indexation Client 2026'!$H$41+$H$41 -> 1.6070443 | K41: =((('indice Carburant'!E13/'Indexation Client 2026'!$D$41)-1)*'Indexation Client 2026'!$F$41)*'Indexation Client 2026'!$H$41+$H$41 -> 1.6026354 | L41: =((('indice Carburant'!F13/'Indexation Client 2026'!$D$41)-1)*'Indexation Client 2026'!$F$41)*'Indexation Client 2026'!$H$41+$H$41 -> 1.6464094 | M41: =((('indice Carburant'!G13/'Indexation Client 2026'!$D$41)-1)*'Indexation Client 2026'!$F$41)*'Indexation Client 2026'!$H$41+$H$41 -> 1.2159852 | N41: =((('indice Carburant'!H13/'Indexation Client 2026'!$D$41)-1)*'Indexation Client 2026'!$F$41)*'Indexation Client 2026'!$H$41+$H$41 -> 1.2159852 | O41: =((('indice Carburant'!I13/'Indexation Client 2026'!$D$41)-1)*'Indexation Client 2026'!$F$41)*'Indexation Client 2026'!$H$41+$H$41 -> 1.2159852 | P41: =((('indice Carburant'!J13/'Indexation Client 2026'!$D$41)-1)*'Indexation Client 2026'!$F$41)*'Indexation Client 2026'!$H$41+$H$41 -> 1.2159852 | Q41: =((('indice Carburant'!K13/'Indexation Client 2026'!$D$41)-1)*'Indexation Client 2026'!$F$41)*'Indexation Client 2026'!$H$41+$H$41 -> 1.2159852 | ... U41: =((('indice Carburant'!O13/'Indexation Client 2026'!$D$41)-1)*'Indexation Client 2026'!$F$41)*'Indexation Client 2026'!$H$41+$H$41 -> 1.2159852
...
