Workbook
Name Moteurs: 'CM4'!#REF!

Sheet Liste
A1: Type vehicule | B1: Energie | C1: Désignation | D1: Loyer actuel | E1: TK Global | F1: Tx Pneu €/km | G1: Tx Entretien €/km | H1: CONSO
A2: Porteur SWAP | B2: GO | C2: =+CONCATENATE(A2,B2) -> Porteur SWAPGO | D2: 2500 | E2: =+F2+G2 -> 0.07 | F2: 0.035 | G2: 0.035 | H2: 30
A3: Tracteur | B3: GO | C3: =+CONCATENATE(A3,B3) -> Tracteur GO | D3: 2300 | E3: =+F3+G3 -> 0.05 | F3: 0.025 | G3: 0.025 | H3: 28
A4: Porteur SWAP | B4: GNC | C4: =+CONCATENATE(A4,B4) -> Porteur SWAPGNC | D4: 3000 | E4: =+F4+G4 -> 0.08 | F4: 0.035 | G4: 0.045 | H4: 33
A5: Tracteur | B5: GNC | C5: =+CONCATENATE(A5,B5) -> Tracteur GNC | D5: 2500 | E5: =+F5+G5 -> 0.06 | F5: 0.025 | G5: 0.035 | H5: 30.5
A7: Aérienne Bachée | C7: =+CONCATENATE(A7,B7) -> Aérienne Bachée | D7: 1200 | E7: =+F7+G7 -> 0.05 | F7: 0.025 | G7: 0.025
A8: Aérienne Classique | C8: =+CONCATENATE(A8,B8) -> Aérienne Classique | D8: 1200 | E8: =+F8+G8 -> 0.05 | F8: 0.025 | G8: 0.025
A9: Aérienne Frigo | C9: =+CONCATENATE(A9,B9) -> Aérienne Frigo | D9: 1400 | E9: =+F9+G9 -> 0.05 | F9: 0.025 | G9: 0.025
A10: Aérienne Méga | C10: =+CONCATENATE(A10,B10) -> Aérienne Méga | D10: 1400 | E10: =+F10+G10 -> 0.05 | F10: 0.025 | G10: 0.025
A11: SR Classique | C11: =+CONCATENATE(A11,B11) -> SR Classique | D11: 1000 | E11: =+F11+G11 -> 0.05 | F11: 0.025 | G11: 0.025
A12: SR Frigo | C12: =+CONCATENATE(A12,B12) -> SR Frigo | D12: 1400 | E12: =+F12+G12 -> 0.05 | F12: 0.025 | G12: 0.025
A13: SR Méga & Frigo | C13: =+CONCATENATE(A13,B13) -> SR Méga & Frigo | D13: 1400 | E13: =+F13+G13 -> 0.05 | F13: 0.025 | G13: 0.025
A14: SR Porte Conteneur | C14: =+CONCATENATE(A14,B14) -> SR Porte Conteneur | D14: 400 | E14: =+F14+G14 -> 0.07 | F14: 0.035 | G14: 0.035
A15: Remorque SWAP | C15: =+CONCATENATE(A15,B15) -> Remorque SWAP | D15: 400 | E15: =+F15+G15 -> 0.07 | F15: 0.035 | G15: 0.035
A16: AUCUNE | C16: =+CONCATENATE(A16,B16) -> AUCUNE | D16: 0
A17: Loyer = Loyer + Assurance + Geoloc
A18: Tirpalette | B18: 55.28 | C18: Mois
A20: Taux horaire
A21: SPL | B21: 1000 | C21: € / hebdo
A22: CM | B22: 1100 | C22: € / Hebdo
A24: OUI
A25: NON

Sheet Sommaire
A1: ETUDES RENTABILITE : AVRIL 2025
K5: Liens | L5: % Marge
A6: Tournée | B6: Client | C6: Conducteur 1 | D6: Conducteur 2 | E6: Conducteur 3 | F6: Lignes | G6: Liens | H6: % Marge | J6: CUMUL CM | K6: CUMUL CM | L6: ='Cumul CM'!D48 -> 0.17798099
A7: SPL7 | B7: STG | C7: ='SPL7'!B7 -> AMRAOUI | D7: ='SPL7'!C7 -> TURQUETIL Y. | F7: CREPY + SCAPNOR + ADM | G7: SPL7'!A1 | H7: ='SPL7'!D48 -> -0.13886197
A8: SPL75 | B8: GLS | C8: ='SPL75'!B7 -> JADE ZINE | F8: Trappes- Coudray | G8: SPL75'!A1 | H8: ='SPL75'!D48 -> -0.081202868 | J8: CUMUL SPL | K8: CUMUL SPL | L8: ='CUMUL SPL'!D48 -> 0.21601596
A9: SPL44 | B9: DHL / CHRONOPOST HNI | C9: ='SPL44'!B7 -> FOFANA M. | F9: CAEN - 23R13 | G9: SPL44'!A1 | H9: ='SPL44'!D48 -> -0.077949229
A10: SPL76 | B10: GLS | C10: ='SPL76'!B7 -> EL MOUMNI | F10: Trappes - Coudray - Gennevilliers | G10: SPL76'!A1 | H10: ='SPL76'!D48 -> -0.036739297
A11: CM42 | B11: UPS | C11: ='CM42'!B7 -> MADANI | F11: Lesquin | G11: CM42'!A1 | H11: ='CM42'!D48 -> -0.028390254
A12: CM24 | B12: UPS | C12: ='CM24'!B7 -> MOREL | F12: Tours | G12: CM24'!A1 | H12: ='CM24'!D48 -> -0.012645373
A13: CM48 | B13: UPS | C13: ='CM48'!B7 -> BOUTCHIHI | F13: Le Mans - Angers | H13: ='CM48'!D48 -> -0.0022539431
A14: CM27 | B14: CHRONOPOST | C14: ='CM27'!B7 -> JARDANI | F14: Amiens - Chilly | G14: CM27'!A1 | H14: ='CM27'!D48 -> -0.0005852447
A15: CM4 | B15: DACHSER CERGY / COLISSIMO | C15: ='CM4'!B7 -> VITALI | F15: Parisienne / IDFN-LTH-017-CM | G15: CM4'!A1 | H15: ='CM4'!D48 -> 0.033649267
A16: CM44 | B16: DACHSER CERGY / COLISSIMO | C16: ='CM44'!B7 -> MALLE Karim | D16: ='CM44'!C7 -> PIEL Flavien | F16: NIORT / IDFN-LTH-014-CM | G16: CM44'!A1 | H16: ='CM44'!D49 -> 0.044856021
A17: CM23 | B17: CHRONOPOST RESEAU | C17: ='CM23'!B7 -> ANSEUR | F17: Arras - Rouen | G17: CM23'!A1 | H17: ='CM23'!D48 -> 0.056751615
A18: SPL73 | B18: STG | C18: ='SPL73'!B7 -> BURLACU | F18: Scapnor Matin | G18: SPL73'!A1 | H18: ='SPL73'!D48 -> 0.065171273
A19: CM5 | B19: DACHSER VILLEPARISIS / COLISSIMO | C19: ='CM5'!B7 -> KONTE | D19: ='CM5'!C7 -> DAJ Victor | E19: ='CM5'!D7 -> ABDAL | F19: T962 / LA VERRIE / IDFN-LTH-004-CM | G19: CM5'!A1 | H19: ='CM5'!D49 -> 0.07338738
A20: SPL45 | B20: DHL | C20: ='SPL45'!B7 -> TATAR M. | F20: Tours | G20: SPL45'!A1 | H20: ='SPL45'!D48 -> 0.074034289
A21: SPL54 | B21: DHL - CHRONOPOST | C21: ='SPL54'!B7 -> JEBALI | F21: Troyes | G21: SPL54'!A1 | H21: ='SPL54'!D48 -> 0.076281167
A22: CM26 | B22: CHRONOPOST | C22: ='CM26'!B7 -> BENALI | F22: ARRAS - Aulnay | G22: CM26'!A1 | H22: ='CM26'!D48 -> 0.078860025
A23: SPL22 | B23: STG | C23: ='SPL22'!B7 -> TOUHAMI | F23: Barbery | G23: SPL22'!A1 | H23: ='SPL22'!D48 -> 0.08536904
A24: CM60 | B24: COLISSIMO | C24: ='CM60'!B7 -> MOROAINU ION | F24: Creil | G24: CM60'!A1 | H24: ='CM60'!D48 -> 0.092716275
A25: SPL8 | B25: GLS | C25: ='SPL8'!B7 -> PARISOT | F25: Coudray - Troyes | G25: SPL8'!A1 | H25: ='SPL8'!D48 -> 0.10224958
A26: SPL74 | B26: VIAPOSTE - CHRONOPOST | C26: ='SPL74'!B7 -> OLIMPIO (AT) | D26: ='SPL74'!C7 -> BENDRIF | F26: Lot 163 | G26: SPL74'!A1 | H26: ='SPL74'!D48 -> 0.10284571
A27: SPL53 | B27: DHL | C27: ='SPL53'!B7 -> DIFALLAH | F27: REIMS | G27: SPL53'!A1 | H27: ='SPL53'!D48 -> 0.11111696
A28: SPL13 | B28: CEVA / VIAPOSTE | C28: ='SPL13'!B7 -> BODEA | D28: ='SPL13'!C7 -> VIVIENS | F28: Kiabi + Lot 170 | G28: SPL13'!A1 | H28: ='SPL13'!D48 -> 0.11801566
A29: CM61 | B29: PARC NANTERRE | C29: ='CM61'!B7 -> ALI MOHAMED | G29: CM61'!A1 | H29: ='CM61'!D48 -> 0.12323997
A30: CM53 | B30: DACHSER CERGY / COLISSIMO | C30: ='CM53'!B7 -> HAMMADI Redha | D30: ='CM53'!C7 -> TAGMI Karim | F30: NANTES / IDFN-LTH-017-CM | G30: CM53'!A1 | H30: ='CM53'!D49 -> 0.1238652
A31: SPL33 | B31: STG | C31: ='SPL33'!B7 -> MOREIRA | F31: SU Nanteuil | G31: SPL33'!A1 | H31: ='SPL33'!D48 -> 0.12679643
A32: CM34 | B32: CHRONOPOST | C32: ='CM34'!B7 -> Faveur | F32: Aulnay - Orleans | G32: CM34'!A1 | H32: ='CM34'!D48 -> 0.13142815
A33: CM29 | B33: CHRONOPOST | C33: ='CM29'!B7 -> BOUGHEZAL | F33: Arras - Seclin | G33: CM29'!A1 | H33: ='CM29'!D48 -> 0.13988954
A34: CM6 | B34: DACHSER CERGY / Chronopost Reseau | C34: ='CM6'!B7 -> TATAR F. | F34: Orleans / Beaugrenelle | G34: CM6'!A1 | H34: ='CM6'!D48 -> 0.14442794
A35: CM21 | B35: TAB | C35: ='CM21'!B7 -> BAJURA | F35: TAB : Petite Caisse | G35: CM21'!A1 | H35: ='CM21'!D48 -> 0.14879782
A36: SPL77 | B36: GLS | C36: ='SPL77'!B7 -> KONE | F36: Coudray - Gennevilliers | G36: SPL77'!A1 | H36: ='SPL77'!D48 -> 0.15483819
A37: SPL36 | B37: VIAPOSTE | C37: ='SPL36'!B7 -> SAGAL | D37: ='SPL36'!C7 -> LATIFA | F37: LOT163-170 | G37: SPL36'!A1 | H37: ='SPL36'!D48 -> 0.15509409
A38: SPL14 | B38: VIAPOSTE / CHRONOPOST | C38: ='SPL14'!B7 -> DIALLO O. | D38: ='SPL14'!C7 -> KAMARA | F38: Lot163 - Dyson | G38: SPL14'!A1 | H38: ='SPL14'!D49 -> 0.1618651
A39: SPL9 | B39: FEDEX GB4 | C39: ='SPL9'!B7 -> WILSON | F39: GB4 | G39: SPL9'!A1 | H39: ='SPL9'!D48 -> 0.16648161
A40: SPL62 | B40: MONDIAL RELAY - UPS | C40: ='SPL62'!B7 -> CISSE M. | F40: Oscaro - Fontenay tressigny | G40: SPL62'!A1 | H40: ='SPL62'!D48 -> 0.16662613
A41: CM14 | B41: CHRONOPOST RESEAU / COLISSIMO | C41: ='CM14'!B7 -> BEZDIGA | D41: ='CM14'!C7 -> ANDRY | F41: Bourges / IDFN-DOT-00A-CM | G41: CM14'!A1 | H41: ='CM14'!D48 -> 0.16789322
A42: SPL72 | B42: DACHSER PANTIN | C42: ='SPL72'!B7 -> Hanzi | F42: PERNOD | G42: SPL72'!A1 | H42: ='SPL72'!D48 -> 0.16894883
A43: SPL51 | B43: TAB | C43: ='SPL51'!B7 -> BAHYAYA | F43: TAB : Grande Caisse | G43: SPL51'!A1 | H43: ='SPL51'!D48 -> 0.16996499
...

Sheet CM4
A1: FICHE DE RENTABILITE
A3: DONNEES EXPLOITATION
B4: Immatriculation | D4: Conso au 100 (Moyenne) | F4: Semaine | G4: S15
A5: Tracteur (s) | B5: FV-146-XG | D5: 37.58
A6: Semi (s) | B6: Remorque | D6: 0.019
A7: Conducteurs | B7: VITALI
A8: AMPLITUDE Hebdo | B8: 67.45
A9: TDS Hebdo | B9: 49.69
B10: KM Hebdo | G10: Hotel (semaine)
B11: 2098 | G11: 0
A12: Autoroute / jour : | B12: 0 | F12: SPL | G12: CM
E13: €/ Hebdo | F13: 1000 | G13: 1100
A14: Détails CA
A15: Référence prestations | B15: Fréquence | C15: Montant unitaire | D15: Quantité | E15: Total Hors IGO | F15: Indexation | G15: Montant Total
A16: DACHSER Cergy : Parisienne | B16: Lundi => Vendredi | C16: 360.2 | D16: 5 | E16: =C16*D16 -> 1801 | F16: -0.0444 | G16: =(E16*F16)+E16 -> 1721.0356
A17: COLISSIMO : IDFN-LTH-017-CM | B17: Mardi => Samedi | C17: 2.5021 | D17: =92*5 -> 460 | E17: =C17*D17 -> 1150.966 | F17: 0 | G17: =(E17*F17)+E17 -> 1150.966
A18: WE : FEDEX GB4 (Dimanche) | B18: Dimanche | C18: 335 | D18: 1 | E18: =C18*D18 -> 335 | F18: 0 | G18: =(E18*F18)+E18 -> 335
E19: =C19*D19 -> 0 | G19: =(E19*F19)+E19 -> 0
E20: =C20*D20 -> 0 | G20: =(E20*F20)+E20 -> 0
E21: =C21*D21 -> 0 | G21: =(E21*F21)+E21 -> 0
E22: =C22*D22 -> 0 | G22: =(E22*F22)+E22 -> 0
A24: CM4 | B24: CA DE LA LIGNE | F24: =SUM(G16:G22) -> 3207.0016
A25: SOMMAIRE
A27: Coûts de la Ligne
B28: Type | C28: unité | D28: Cout Semaine
A29: Moteur | B29: Porteur SWAPGO | C29: =IFERROR(VLOOKUP(B29,Liste!C1:D5,2,FALSE),"") -> 2500 | D29: =IFERROR(C29/4.33,0) -> 577.36721
A30: Semi (1) | B30: Remorque SWAP | C30: =IFERROR(VLOOKUP(B30,Liste!$C$7:$D$15,2,FALSE),"") -> 400 | D30: =IFERROR(C30/4.33,0) -> 92.378753
A31: Semi (2) | B31: AUCUNE | C31: =IFERROR(VLOOKUP(B31,Liste!$C$7:$D$15,2,FALSE),"") | D31: =IFERROR(C31/4.33,0) -> 0
A32: Semi (3) | B32: AUCUNE | C32: =IFERROR(VLOOKUP(B32,Liste!$C$7:$D$15,2,FALSE),"") | D32: =IFERROR(C32/4.33,0) -> 0
A33: Semi (4) | B33: AUCUNE | C33: =IFERROR(VLOOKUP(B33,Liste!$C$7:$D$15,2,FALSE),"") | D33: =IFERROR(C33/4.33,0) -> 0
A34: Carburant | B34: GO | C34: 1.3554 | D34: =(B11*D5/100)*C34 -> 1068.6359
A35: Carburant | B35: GNC | C35: 0 | D35: =(D5*B11/100)*C35 -> 0
A36: AD Blue | C36: 0.4309 | D36: =(D6*B11)*C36 -> 17.176536
A37: Fuel | C37: 1.1225
A38: Casse / Pneumatique / Lavage ( hors entretien) | C38: 0.04 | D38: =C38*B11 -> 83.92
A39: Autoroute | B39: =B12 -> 0 | C39: 5 | D39: =C39*B39 -> 0
A40: Salaires | B40: CM | C40: 1 | D40: 1259.61
A41: Frais Hotel | D41: =G11 -> 0
A42: Tirpalette | B42: NON | C42: =IF(B42=Liste!A24,Liste!B18,0) -> 0 | D42: =C42/4.33 -> 0
A43: Sous-Traitance | C43: 0 | D43: 0
...

Sheet CM6
A1: FICHE DE RENTABILITE
A3: DONNEES EXPLOITATION
B4: Immatriculation | D4: Conso au 100 (Moyenne) | F4: Semaine | G4: S15
A5: Tracteur (s) | B5: GY-247-BQ | D5: 23.82
A6: Semi (s) | B6: Remorque | D6: 0.019
A7: Conducteurs | B7: TATAR F.
A8: AMPLITUDE Hebdo | B8: 57.07
A9: TDS Hebdo | B9: 44.82
B10: KM Hebdo | G10: Hotel (semaine)
B11: 2633 | G11: 0
A12: Autoroute / jour : | B12: 34.16 | C12: (non Facturé) | F12: SPL | G12: CM
E13: €/ Hebdo | F13: 1000 | G13: 1100
A14: Détails CA
A15: Référence prestations | B15: Fréquence | C15: Montant unitaire | D15: Quantité | E15: Total Hors IGO | F15: Indexation | G15: Montant Total
A16: DACHSER CERGY : Orléans | B16: Lundi => Vendredi | C16: 483.3 | D16: 5 | E16: =C16*D16 -> 2416.5 | F16: -0.0392 | G16: =(E16*F16)+E16 -> 2321.7732
A17: CHRONOPOST : 31010 | B17: Mardi => Samedi | C17: 283 | D17: 5 | E17: =C17*D17 -> 1415 | F17: =13.44*5 -> 67.2 | G17: =(E17+F17) -> 1482.2 | I17: Indexation Gaz sur porteur GO
A18: Tourne sur 5 Jours | E18: =C18*D18 -> 0 | G18: =(E18*F18)+E18 -> 0
E19: =C19*D19 -> 0 | G19: =(E19*F19)+E19 -> 0
E20: =C20*D20 -> 0 | G20: =(E20*F20)+E20 -> 0
E21: =C21*D21 -> 0 | G21: =(E21*F21)+E21 -> 0
E22: =C22*D22 -> 0 | G22: =(E22*F22)+E22 -> 0
A24: CM6 | B24: CA DE LA LIGNE | F24: =SUM(G16:G22) -> 3803.9732
A25: SOMMAIRE
A27: Coûts de la Ligne
B28: Type | C28: unité | D28: Cout Semaine
A29: Moteur | B29: Porteur SWAPGO | C29: =IFERROR(VLOOKUP(B29,Liste!C1:D5,2,FALSE),"") -> 2500 | D29: =IFERROR(C29/4.33,0) -> 577.36721
A30: Semi (1) | B30: Remorque SWAP | C30: =IFERROR(VLOOKUP(B30,Liste!$C$7:$D$15,2,FALSE),"") -> 400 | D30: =IFERROR(C30/4.33,0) -> 92.378753
A31: Semi (2) | B31: AUCUNE | C31: =IFERROR(VLOOKUP(B31,Liste!$C$7:$D$15,2,FALSE),"") | D31: =IFERROR(C31/4.33,0) -> 0
A32: Semi (3) | B32: AUCUNE | C32: =IFERROR(VLOOKUP(B32,Liste!$C$7:$D$15,2,FALSE),"") | D32: =IFERROR(C32/4.33,0) -> 0
A33: Semi (4) | B33: AUCUNE | C33: =IFERROR(VLOOKUP(B33,Liste!$C$7:$D$15,2,FALSE),"") | D33: =IFERROR(C33/4.33,0) -> 0
A34: Carburant | B34: GO | C34: 1.3554 | D34: =(B11*D5/100)*C34 -> 850.08059
A35: Carburant | B35: GNC | C35: 0 | D35: =(D5*B11/100)*C35 -> 0
A36: AD Blue | C36: 0.4309 | D36: =(D6*B11)*C36 -> 21.556634
A37: Fuel | C37: 1.1225
A38: Casse / Pneumatique / Lavage ( hors entretien) | C38: 0.04 | D38: =C38*B11 -> 105.32
A39: Autoroute | B39: =B12 -> 34.16 | C39: 5 | D39: =C39*B39 -> 170.8
A40: Salaires | B40: CM | C40: 1 | D40: 1437.07
A41: Frais Hotel | D41: =G11 -> 0
A42: Tirpalette | B42: NON | C42: =IF(B42=Liste!A24,Liste!B18,0) -> 0 | D42: =C42/4.33 -> 0
A43: Sous-Traitance | C43: 0 | D43: 0
...

Sheet CM8
A1: FICHE DE RENTABILITE
A3: DONNEES EXPLOITATION
B4: Immatriculation | D4: Conso au 100 (Moyenne) | F4: Semaine | G4: S16
A5: Tracteur (s) | B5: GX-734-TC | D5: 28.45
A6: Semi (s) | B6: Remorque | D6: 0.019
A7: Conducteurs | B7: AZZOUZ Nordine | C7: AZZOUZ Mustapha
A8: AMPLITUDE Hebdo | B8: 38.84 | C8: 65.47
A9: TDS Hebdo | B9: 32.79 | C9: 46.84
B10: KM Hebdo | G10: Hotel (semaine)
B11: 4328 | G11: 0
A12: Autoroute / jour : | B12: 164 | C12: 152.69 | F12: SPL | G12: CM
E13: €/ Hebdo | F13: 1000 | G13: 1100
A14: Détails CA
A15: Référence prestations | B15: Fréquence | C15: Montant unitaire | D15: Quantité | E15: Total Hors IGO | F15: Indexation | G15: Montant Total
A16: DACHSER Villeparisis : T962 | B16: Lundi => Vendredi | C16: 367 | D16: 5 | E16: =C16*D16 -> 1835 | F16: 0.0729 | G16: =(E16*F16)+E16 -> 1968.7715
A17: DACHSER Villeparisis : Uberherrn | B17: Lundi => Vendredi | C17: 907.69 | D17: 5 | E17: =C17*D17 -> 4538.45 | F17: 0.1072 | G17: =((E17-(C12*5))*F17)+E17 -> 4943.13
E18: =C18*D18 -> 0 | G18: =(E18*F18)+E18 -> 0
A19: Tourne sur 5 Jours | E19: =C19*D19 -> 0 | G19: =(E19*F19)+E19 -> 0
E20: =C20*D20 -> 0 | G20: =(E20*F20)+E20 -> 0
E21: =C21*D21 -> 0 | G21: =(E21*F21)+E21 -> 0
E22: =C22*D22 -> 0 | G22: =(E22*F22)+E22 -> 0
A24: CM8 | B24: CA DE LA LIGNE | F24: =SUM(G16:G22) -> 6911.9015
A25: SOMMAIRE
A27: Coûts de la Ligne
B28: Type | C28: unité | D28: Cout Semaine
A29: Moteur | B29: Porteur SWAPGO | C29: =IFERROR(VLOOKUP(B29,Liste!C1:D5,2,FALSE),"") -> 2500 | D29: =IFERROR(C29/4.33,0) -> 577.36721
A30: Semi (1) | B30: Remorque SWAP | C30: =IFERROR(VLOOKUP(B30,Liste!$C$7:$D$15,2,FALSE),"") -> 400 | D30: =IFERROR(C30/4.33,0) -> 92.378753
A31: Semi (2) | B31: AUCUNE | C31: =IFERROR(VLOOKUP(B31,Liste!$C$7:$D$15,2,FALSE),"") | D31: =IFERROR(C31/4.33,0) -> 0
A32: Semi (3) | B32: AUCUNE | C32: =IFERROR(VLOOKUP(B32,Liste!$C$7:$D$15,2,FALSE),"") | D32: =IFERROR(C32/4.33,0) -> 0
A33: Semi (4) | B33: AUCUNE | C33: =IFERROR(VLOOKUP(B33,Liste!$C$7:$D$15,2,FALSE),"") | D33: =IFERROR(C33/4.33,0) -> 0
A34: Carburant | B34: GO | C34: 1.3554 | D34: =(B11*D5/100)*C34 -> 1668.9257
A35: Carburant | B35: GNC | C35: 0 | D35: =(D5*B11/100)*C35 -> 0
A36: AD Blue | C36: 0.4309 | D36: =(D6*B11)*C36 -> 35.433769
A37: Fuel | C37: 1.1225
A38: Casse / Pneumatique / Lavage ( hors entretien) | C38: 0.04 | D38: =C38*B11 -> 173.12
A39: Autoroute | B39: =B12 -> 164 | C39: 5 | D39: =C39*B39 -> 820
A40: Salaires | B40: CM | C40: 2 | D40: =1016.6+975.01 -> 1991.61
A41: Frais Hotel | D41: =G11 -> 0
A42: Tirpalette | B42: NON | C42: =IF(B42=Liste!A24,Liste!B18,0) -> 0 | D42: =C42/4.33 -> 0
A43: Sous-Traitance | C43: 0 | D43: 0
...

Sheet CM9
A1: FICHE DE RENTABILITE
A3: DONNEES EXPLOITATION
B4: Immatriculation | D4: Conso au 100 (Moyenne) | F4: Semaine | G4: S16
A5: Tracteur (s) | B5: GX-202-QC | D5: 26.88
A6: Semi (s) | B6: Remorque | D6: 0.019
A7: Conducteurs | B7: MIC Marius | C7: OUAHABI Mourad
A8: AMPLITUDE Hebdo | B8: 49.09 | C8: 52.24
A9: TDS Hebdo | B9: 37.59 | C9: 47.2
B10: KM Hebdo | G10: Hotel (semaine)
B11: =879+3656 -> 4535 | G11: 0
A12: Autoroute / jour : | B12: 127.67 | C12: 102.99 | F12: SPL | G12: CM
E13: €/ Hebdo | F13: 1000 | G13: 1100
A14: Détails CA
A15: Référence prestations | B15: Fréquence | C15: Montant unitaire | D15: Quantité | E15: Total Hors IGO | F15: Indexation | G15: Montant Total
A16: DACHSER Villeparisis : T964 | B16: Lundi => Vendredi | C16: 367 | D16: 5 | E16: =C16*D16 -> 1835 | F16: 0.0729 | G16: =(E16*F16)+E16 -> 1968.7715
A17: DACHSER Villeparisis : Dijon | B17: Lundi => Vendredi | C17: 854.89 | D17: 5 | E17: =C17*D17 -> 4274.45 | F17: 0.1082 | G17: =((E17-(C12*5))*F17)+E17 -> 4681.2279
A18: CHRONOPOST : 27860 | B18: Lundi | C18: 300 | D18: 1 | E18: =C18*D18 -> 300 | F18: =80*0.2922 -> 23.376 | G18: =(E18+F18) -> 323.376
E19: =C19*D19 -> 0 | G19: =(E19*F19)+E19 -> 0
A20: Tourne sur 5 Jours | E20: =C20*D20 -> 0 | G20: =(E20*F20)+E20 -> 0
E21: =C21*D21 -> 0 | G21: =(E21*F21)+E21 -> 0
E22: =C22*D22 -> 0 | G22: =(E22*F22)+E22 -> 0
A24: CM9 | B24: CA DE LA LIGNE | F24: =SUM(G16:G22) -> 6973.3754
A25: SOMMAIRE
A27: Coûts de la Ligne
B28: Type | C28: unité | D28: Cout Semaine
A29: Moteur | B29: Porteur SWAPGO | C29: =IFERROR(VLOOKUP(B29,Liste!C1:D5,2,FALSE),"") -> 2500 | D29: =IFERROR(C29/4.33,0) -> 577.36721
A30: Semi (1) | B30: Remorque SWAP | C30: =IFERROR(VLOOKUP(B30,Liste!$C$7:$D$15,2,FALSE),"") -> 400 | D30: =IFERROR(C30/4.33,0) -> 92.378753
A31: Semi (2) | B31: AUCUNE | C31: =IFERROR(VLOOKUP(B31,Liste!$C$7:$D$15,2,FALSE),"") | D31: =IFERROR(C31/4.33,0) -> 0
A32: Semi (3) | B32: AUCUNE | C32: =IFERROR(VLOOKUP(B32,Liste!$C$7:$D$15,2,FALSE),"") | D32: =IFERROR(C32/4.33,0) -> 0
A33: Semi (4) | B33: AUCUNE | C33: =IFERROR(VLOOKUP(B33,Liste!$C$7:$D$15,2,FALSE),"") | D33: =IFERROR(C33/4.33,0) -> 0
A34: Carburant | B34: GO | C34: 1.3554 | D34: =(B11*D5/100)*C34 -> 1652.2434
A35: Carburant | B35: GNC | C35: 0 | D35: =(D5*B11/100)*C35 -> 0
A36: AD Blue | C36: 0.4309 | D36: =(D6*B11)*C36 -> 37.128498
A37: Fuel | C37: 1.1225
A38: Casse / Pneumatique / Lavage ( hors entretien) | C38: 0.04 | D38: =C38*B11 -> 181.4
A39: Autoroute | B39: =B12 -> 127.67 | C39: 5 | D39: =C39*B39 -> 638.35
A40: Salaires | B40: CM | C40: 2 | D40: =791.12+1148.93 -> 1940.05
A41: Frais Hotel | D41: =G11 -> 0
A42: Tirpalette | B42: NON | C42: =IF(B42=Liste!A24,Liste!B18,0) -> 0 | D42: =C42/4.33 -> 0
A43: Sous-Traitance | C43: 0 | D43: 0
...

Sheet CM10
A1: FICHE DE RENTABILITE
A3: DONNEES EXPLOITATION
B4: Immatriculation | D4: Conso au 100 (Moyenne) | F4: Semaine | G4: S16
A5: Tracteur (s) | B5: FB730VT | D5: 34.24
A6: Semi (s) | B6: Remorque | D6: 0.019
A7: Conducteurs | B7: BEZZAOUYA
A8: AMPLITUDE Hebdo | B8: 69.07
A9: TDS Hebdo | B9: 59.7
B10: KM Hebdo | G10: Hotel (semaine)
B11: 2263 | G11: 0
A12: Autoroute / jour : | B12: 21 | C12: (non Facturé) | F12: SPL | G12: CM
E13: €/ Hebdo | F13: 1000 | G13: 1100
A14: Détails CA
A15: Référence prestations | B15: Fréquence | C15: Montant unitaire | D15: Quantité | E15: Total Hors IGO | F15: Indexation | G15: Montant Total
A16: DACHSER VILLEPARISIS : Rouen | B16: Lundi => Vendredi | C16: 565 | D16: 5 | E16: =C16*D16 -> 2825 | F16: 0.0208 | G16: =(E16*F16)+E16 -> 2883.76
A17: CHRONOPOST : 29096 | B17: Mardi => Samedi | C17: 265 | D17: 5 | E17: =C17*D17 -> 1325 | F17: =(70*5)*0.2922 -> 102.27 | G17: =(E17+F17) -> 1427.27
A18: WE : Viapost : 170-14 | B18: Dimanche | C18: 96.85 | D18: 1 | E18: =C18*D18 -> 96.85 | F18: 0.04271 | G18: =(E18*F18)+E18 -> 100.98646 | I18: Activité en Semi
A19: WE : Viapost : 164-14/22 | B19: Dimanche | C19: =210.67+160.79 -> 371.46 | D19: 1 | E19: =C19*D19 -> 371.46 | F19: 0.039775 | G19: =(E19*F19)+E19 -> 386.23482
E20: =C20*D20 -> 0 | G20: =(E20*F20)+E20 -> 0
E21: =C21*D21 -> 0 | G21: =(E21*F21)+E21 -> 0
E22: =C22*D22 -> 0 | G22: =(E22*F22)+E22 -> 0
A24: CM10 | B24: CA DE LA LIGNE | F24: =SUM(G16:G22) -> 4798.2513
A25: SOMMAIRE
A27: Coûts de la Ligne
B28: Type | C28: unité | D28: Cout Semaine
A29: Moteur | B29: Porteur SWAPGO | C29: =IFERROR(VLOOKUP(B29,Liste!C1:D5,2,FALSE),"") -> 2500 | D29: =IFERROR(C29/4.33,0) -> 577.36721
A30: Semi (1) | B30: Remorque SWAP | C30: =IFERROR(VLOOKUP(B30,Liste!$C$7:$D$15,2,FALSE),"") -> 400 | D30: =IFERROR(C30/4.33,0) -> 92.378753
A31: Semi (2) | B31: AUCUNE | C31: =IFERROR(VLOOKUP(B31,Liste!$C$7:$D$15,2,FALSE),"") | D31: =IFERROR(C31/4.33,0) -> 0
A32: Semi (3) | B32: AUCUNE | C32: =IFERROR(VLOOKUP(B32,Liste!$C$7:$D$15,2,FALSE),"") | D32: =IFERROR(C32/4.33,0) -> 0
A33: Semi (4) | B33: AUCUNE | C33: =IFERROR(VLOOKUP(B33,Liste!$C$7:$D$15,2,FALSE),"") | D33: =IFERROR(C33/4.33,0) -> 0
A34: Carburant | B34: GO | C34: 1.3554 | D34: =(B11*D5/100)*C34 -> 1050.2333
A35: Carburant | B35: GNC | C35: 0 | D35: =(D5*B11/100)*C35 -> 0
A36: AD Blue | C36: 0.4309 | D36: =(D6*B11)*C36 -> 18.527407
A37: Fuel | C37: 1.1225
A38: Casse / Pneumatique / Lavage ( hors entretien) | C38: 0.04 | D38: =C38*B11 -> 90.52
A39: Autoroute | B39: =B12 -> 21 | C39: 5 | D39: =C39*B39 -> 105
A40: Salaires | B40: CM | C40: 1 | D40: 972.68
A41: Frais Hotel | D41: =G11 -> 0
A42: Tirpalette | B42: NON | C42: =IF(B42=Liste!A24,Liste!B18,0) -> 0 | D42: =C42/4.33 -> 0
A43: Sous-Traitance | C43: 0 | D43: 0
...

Sheet CM5
A1: FICHE DE RENTABILITE
A3: DONNEES EXPLOITATION
B4: Immatriculation | D4: Conso au 100 (Moyenne) | F4: Semaine | G4: S16
A5: Tracteur (s) | B5: FC-240-JS | C5: GB-212-EM | D5: 30.82
A6: Semi (s) | B6: Remorque | C6: Remorque | D6: 0.019
A7: Conducteurs | B7: KONTE | C7: DAJ Victor | D7: ABDAL
A8: AMPLITUDE Hebdo | B8: 50.62 | C8: 36.71 | D8: 43.05
A9: TDS Hebdo | B9: 40.65 | C9: 31.83 | D9: 37.27
B10: KM Hebdo | G10: Hotel (semaine)
B11: =2404+2153+1248 -> 5805 | G11: 0
A12: Autoroute / jour : | B12: 191 | C12: 152.86 | F12: SPL | G12: CM
E13: €/ Hebdo | F13: 1000 | G13: 1100
A14: Détails CA
A15: Référence prestations | B15: Fréquence | C15: Montant unitaire | D15: Quantité | E15: Total Hors IGO | F15: Indexation | G15: Montant Total
A16: DACHSER Villeparisis : LA VERRIE | B16: Lundi => Vendredi | C16: 1164.26 | D16: 5 | E16: =C16*D16 -> 5821.3 | F16: 0.0614 | G16: =((E16-(C12*5))*F16)+E16 -> 6131.7998
A17: COLISSIMO : IDF-LTH-004-CM | B17: Mardi => Samedi | C17: 4.1631 | D17: =10*5 -> 50 | E17: =C17*D17 -> 208.155 | F17: 0 | G17: =(E17*F17)+E17 -> 208.155
A18: DACHSER Villeparisis : T962 | B18: Lundi => Vendredi | C18: 367 | D18: 5 | E18: =C18*D18 -> 1835 | F18: 0.0729 | G18: =(E18*F18)+E18 -> 1968.7715
A19: Daj + Abdal = 5 jours semaine | E19: =C19*D19 -> 0 | G19: =(E19*F19)+E19 -> 0
A20: WE: (Konte) FEDEX FRT03410 | B20: Dimanche | C20: 160 | D20: 1 | E20: =C20*D20 -> 160 | F20: -0.0091 | G20: =(E20*F20)+E20 -> 158.544
A21: WE: (Konte) DHL FR9894C | B21: Dimanche | C21: 190 | D21: 1 | E21: =C21*D21 -> 190 | F21: -0.0301 | G21: =(E21*F21)+E21 -> 184.281
A22: WE : (Konte ) FEDEX FRT03381 | B22: Dimanche | C22: 132.5 | D22: 1 | E22: =C22*D22 -> 132.5 | F22: -0.0091 | G22: =(E22*F22)+E22 -> 131.29425
A24: CM5 | B24: CA DE LA LIGNE | F24: =SUM(G16:G22) -> 8782.8456
A25: SOMMAIRE
A27: Coûts de la Ligne
B28: Type | C28: unité | D28: Cout Semaine
A29: Moteur (1) | B29: Porteur SWAPGO | C29: =IFERROR(VLOOKUP(B29,Liste!C1:D5,2,FALSE),"") -> 2500 | D29: =IFERROR(C29/4.33,0) -> 577.36721
A30: Moteur (2) | B30: Porteur SWAPGO | C30: =IFERROR(VLOOKUP(B30,Liste!C2:D6,2,FALSE),"") -> 2500 | D30: =IFERROR(C30/4.33,0) -> 577.36721
A31: Semi (1) | B31: Remorque SWAP | C31: =IFERROR(VLOOKUP(B31,Liste!$C$7:$D$15,2,FALSE),"") -> 400 | D31: =IFERROR(C31/4.33,0) -> 92.378753
A32: Semi (2) | B32: Remorque SWAP | C32: =IFERROR(VLOOKUP(B32,Liste!$C$7:$D$15,2,FALSE),"") -> 400 | D32: =IFERROR(C32/4.33,0) -> 92.378753
A33: Semi (3) | B33: AUCUNE | C33: =IFERROR(VLOOKUP(B33,Liste!$C$7:$D$15,2,FALSE),"") | D33: =IFERROR(C33/4.33,0) -> 0
A34: Semi (4) | B34: AUCUNE | C34: =IFERROR(VLOOKUP(B34,Liste!$C$7:$D$15,2,FALSE),"") | D34: =IFERROR(C34/4.33,0) -> 0
A35: Carburant | B35: GO | C35: 1.3554 | D35: =(B11*D5/100)*C35 -> 2424.9475
A36: Carburant | B36: GNC | C36: 0 | D36: =(D5*B11/100)*C36 -> 0
A37: AD Blue | C37: 0.4309 | D37: =(D6*B11)*C37 -> 47.526116
A38: Fuel | C38: 1.1225
A39: Casse / Pneumatique / Lavage ( hors entretien) | C39: 0.04 | D39: =C39*B11 -> 232.2
A40: Autoroute | B40: =B12 -> 191 | C40: 5 | D40: =C40*B40 -> 955
A41: Salaires | B41: CM | C41: 3 | D41: =1039.77+1002.21+1097.15 -> 3139.13
A42: Frais Hotel | D42: =G11 -> 0
A43: Tirpalette | B43: NON | C43: =IF(B43=Liste!A24,Liste!B18,0) -> 0 | D43: =C43/4.33 -> 0
...

Sheet CM44
A1: FICHE DE RENTABILITE
A3: DONNEES EXPLOITATION
B4: Immatriculation | D4: Conso au 100 (Moyenne) | F4: Semaine | G4: S16
A5: Tracteur (s) | B5: GN-649-LZ | C5: GN-276-WA | D5: 30.5
A6: Semi (s) | B6: Remorque | C6: Remorque | D6: 0.019
A7: Conducteurs | B7: MALLE Karim | C7: PIEL Flavien
A8: AMPLITUDE Hebdo | B8: 55.22 | C8: 47.82
A9: TDS Hebdo | B9: 48.73 | C9: 43.79
B10: KM Hebdo | G10: Hotel (semaine)
B11: =2458+2776 -> 5234 | G11: 0
A12: Autoroute / jour : | B12: 178.66 | C12: 150.61 | F12: SPL | G12: CM
E13: €/ Hebdo | F13: 1000 | G13: 1100
A14: Détails CA
A15: Référence prestations | B15: Fréquence | C15: Montant unitaire | D15: Quantité | E15: Total Hors IGO | F15: Indexation | G15: Montant Total
A16: DACHSER Cergy : NIORT | B16: Lundi => Vendredi | C16: 1320.84 | D16: 5 | E16: =C16*D16 -> 6604.2 | F16: -0.0406 | G16: =((E16-(C12*5))*F16)+E16 -> 6366.6433
A17: Colissimo - IDFN-LTH-014-CM | B17: Mercredi et Jeudi | C17: 2.5043 | D17: =56*2 -> 112 | E17: =C17*D17 -> 280.4816 | G17: =(E17*F17)+E17 -> 280.4816
A18: Piel sur 5 Jours / Semaine | E18: =C18*D18 -> 0 | G18: =(E18*F18)+E18 -> 0
A19: WE : (MALLE) : Colissimo DOT-00A-CM | B19: Samedi | C19: 2.4411 | D19: 50 | E19: =C19*D19 -> 122.055 | G19: =(E19*F19)+E19 -> 122.055
A20: WE : (Malle) CHRONOPOST : LWCDGHNI02 | B20: Samedi | C20: 65 | D20: 1 | E20: =C20*D20 -> 65 | F20: =14*0.2922 -> 4.0908 | G20: =F20+E20 -> 69.0908
E21: =C21*D21 -> 0 | G21: =(E21*F21)+E21 -> 0
E22: =C22*D22 -> 0 | G22: =(E22*F22)+E22 -> 0
A24: CM44 | B24: CA DE LA LIGNE | F24: =SUM(G16:G22) -> 6838.2707
A25: SOMMAIRE
A27: Coûts de la Ligne
B28: Type | C28: unité | D28: Cout Semaine
A29: Moteur (1) | B29: Porteur SWAPGO | C29: =IFERROR(VLOOKUP(B29,Liste!C1:D5,2,FALSE),"") -> 2500 | D29: =IFERROR(C29/4.33,0) -> 577.36721
A30: Moteur (2) | B30: Porteur SWAPGO | C30: =IFERROR(VLOOKUP(B30,Liste!C2:D6,2,FALSE),"") -> 2500 | D30: =IFERROR(C30/4.33,0) -> 577.36721
A31: Semi (1) | B31: Remorque SWAP | C31: =IFERROR(VLOOKUP(B31,Liste!$C$7:$D$15,2,FALSE),"") -> 400 | D31: =IFERROR(C31/4.33,0) -> 92.378753
A32: Semi (2) | B32: Remorque SWAP | C32: =IFERROR(VLOOKUP(B32,Liste!$C$7:$D$15,2,FALSE),"") -> 400 | D32: =IFERROR(C32/4.33,0) -> 92.378753
A33: Semi (3) | B33: AUCUNE | C33: =IFERROR(VLOOKUP(B33,Liste!$C$7:$D$15,2,FALSE),"") | D33: =IFERROR(C33/4.33,0) -> 0
A34: Semi (4) | B34: AUCUNE | C34: =IFERROR(VLOOKUP(B34,Liste!$C$7:$D$15,2,FALSE),"") | D34: =IFERROR(C34/4.33,0) -> 0
A35: Carburant | B35: GO | C35: 1.3554 | D35: =(B11*D5/100)*C35 -> 2163.7199
A36: Carburant | B36: GNC | C36: 0 | D36: =(D5*B11/100)*C36 -> 0
A37: AD Blue | C37: 0.4309 | D37: =(D6*B11)*C37 -> 42.851281
A38: Fuel | C38: 1.1225
A39: Casse / Pneumatique / Lavage ( hors entretien) | C39: 0.04 | D39: =C39*B11 -> 209.36
A40: Autoroute | B40: =B12 -> 178.66 | C40: 5 | D40: =C40*B40 -> 893.3
A41: Salaires | B41: CM | C41: 2 | D41: =1037.7+845.11 -> 1882.81
A42: Frais Hotel | D42: =G11 -> 0
A43: Tirpalette | B43: NON | C43: =IF(B43=Liste!A24,Liste!B18,0) -> 0 | D43: =C43/4.33 -> 0
...

Sheet CM53
A1: FICHE DE RENTABILITE
A3: DONNEES EXPLOITATION
B4: Immatriculation | D4: Conso au 100 (Moyenne) | F4: Semaine | G4: S16
A5: Tracteur (s) | B5: GY-244-BQ | C5: GN-648-LZ | D5: 28.6
A6: Semi (s) | B6: Remorque | C6: Remorque | D6: 0.019
A7: Conducteurs | B7: HAMMADI Redha | C7: TAGMI Karim
A8: AMPLITUDE Hebdo | B8: 62.66
A9: TDS Hebdo | B9: 52.38
B10: KM Hebdo | G10: Hotel (semaine)
B11: =2912+2389 -> 5301 | G11: 0
A12: Autoroute / jour : | B12: 213.43 | C12: 195.31 | F12: SPL | G12: CM
E13: €/ Hebdo | F13: 1000 | G13: 1100
A14: Détails CA
A15: Référence prestations | B15: Fréquence | C15: Montant unitaire | D15: Quantité | E15: Total Hors IGO | F15: Indexation | G15: Montant Total
A16: DACHSER Cergy : Nantes | B16: Lundi => Vendredi | C16: 1395.31 | D16: 5 | E16: =C16*D16 -> 6976.55 | F16: -0.0365 | G16: =((E16-(C12*5))*F16)+E16 -> 6757.55
A17: COLISSIMO : IDFN-LTH-017-CM | B17: Mardi => Samedi | C17: 2.5021 | D17: =70*5 -> 350 | E17: =C17*D17 -> 875.735 | G17: =(E17*F17)+E17 -> 875.735
E18: =C18*D18 -> 0 | G18: =(E18*F18)+E18 -> 0
A19: WE : (Hammadi) Viaposte 168-2 / 6 | B19: Dimanche | C19: =179.42+104.98 -> 284.4 | D19: 1 | E19: =C19*D19 -> 284.4 | F19: 0.04773 | G19: =(E19*F19)+E19 -> 297.97441
A20: WE : (Hammadi) Viaposte 164-19 | B20: Dimanche | C20: 195.33 | D20: 1 | E20: =C20*D20 -> 195.33 | F20: 0.039775 | G20: =(E20*F20)+E20 -> 203.09925
E21: =C21*D21 -> 0 | G21: =(E21*F21)+E21 -> 0
E22: =C22*D22 -> 0 | G22: =(E22*F22)+E22 -> 0
A24: CM53 | B24: CA DE LA LIGNE | F24: =SUM(G16:G22) -> 8134.3587
A25: SOMMAIRE
A27: Coûts de la Ligne
B28: Type | C28: unité | D28: Cout Semaine
A29: Moteur (1) | B29: Porteur SWAPGO | C29: =IFERROR(VLOOKUP(B29,Liste!C1:D5,2,FALSE),"") -> 2500 | D29: =IFERROR(C29/4.33,0) -> 577.36721
A30: Moteur (2) | B30: Porteur SWAPGO | C30: =IFERROR(VLOOKUP(B30,Liste!C2:D6,2,FALSE),"") -> 2500 | D30: =IFERROR(C30/4.33,0) -> 577.36721
A31: Semi (1) | B31: Remorque SWAP | C31: =IFERROR(VLOOKUP(B31,Liste!$C$7:$D$15,2,FALSE),"") -> 400 | D31: =IFERROR(C31/4.33,0) -> 92.378753
A32: Semi (2) | B32: Remorque SWAP | C32: =IFERROR(VLOOKUP(B32,Liste!$C$7:$D$15,2,FALSE),"") -> 400 | D32: =IFERROR(C32/4.33,0) -> 92.378753
A33: Semi (3) | B33: AUCUNE | C33: =IFERROR(VLOOKUP(B33,Liste!$C$7:$D$15,2,FALSE),"") | D33: =IFERROR(C33/4.33,0) -> 0
A34: Semi (4) | B34: AUCUNE | C34: =IFERROR(VLOOKUP(B34,Liste!$C$7:$D$15,2,FALSE),"") | D34: =IFERROR(C34/4.33,0) -> 0
A35: Carburant | B35: GO | C35: 1.3554 | D35: =(B11*D5/100)*C35 -> 2054.903
A36: Carburant | B36: GNC | C36: 0 | D36: =(D5*B11/100)*C36 -> 0
A37: AD Blue | C37: 0.4309 | D37: =(D6*B11)*C37 -> 43.399817
A38: Fuel | C38: 1.1225
A39: Casse / Pneumatique / Lavage ( hors entretien) | C39: 0.04 | D39: =C39*B11 -> 212.04
A40: Autoroute | B40: =B12 -> 213.43 | C40: 5 | D40: =C40*B40 -> 1067.15
A41: Salaires | B41: CM | C41: 2 | D41: =1451.93+957.88 -> 2409.81
A42: Frais Hotel | D42: =G11 -> 0
A43: Tirpalette | B43: NON | C43: =IF(B43=Liste!A24,Liste!B18,0) -> 0 | D43: =C43/4.33 -> 0
...

Sheet CM7
A1: FICHE DE RENTABILITE
A3: DONNEES EXPLOITATION
B4: Immatriculation | D4: Conso au 100 (Moyenne) | F4: Semaine | G4: S16
A5: Tracteur (s) | B5: FA826ZA | D5: 32
A6: Semi (s) | B6: Remorque | D6: 0.019
A7: Conducteurs | B7: JAMES Fabrice
A8: AMPLITUDE Hebdo | B8: 61.13
A9: TDS Hebdo | B9: 52.78
B10: KM Hebdo | G10: Hotel (semaine)
B11: 2889 | G11: 0
A12: Autoroute / jour : | B12: 0 | F12: SPL | G12: CM
E13: €/ Hebdo | F13: 1000 | G13: 1100
A14: Détails CA
A15: Référence prestations | B15: Fréquence | C15: Montant unitaire | D15: Quantité | E15: Total Hors IGO | F15: Indexation | G15: Montant Total
A16: Coliposte Zalando Vatry | B16: Lundi au Vendredi | C16: 480 | D16: 5 | E16: =C16*D16 -> 2400 | F16: 0 | G16: =(E16*F16)+E16 -> 2400
A17: Coliposte Zalando Vatry | B17: Lundi au Vendredi | C17: 480 | D17: 5 | E17: =C17*D17 -> 2400 | F17: 0 | G17: =(E17*F17)+E17 -> 2400
M18: u
E19: =C19*D19 -> 0 | G19: =(E19*F19)+E19 -> 0
E20: =C20*D20 -> 0 | G20: =(E20*F20)+E20 -> 0
E21: =C21*D21 -> 0 | G21: =(E21*F21)+E21 -> 0
E22: =C22*D22 -> 0 | G22: =(E22*F22)+E22 -> 0
A24: CM7 | B24: CA DE LA LIGNE | F24: =SUM(G16:G22) -> 4800
A25: SOMMAIRE
A27: Coûts de la Ligne
B28: Type | C28: unité | D28: Cout Semaine
A29: Moteur | B29: Porteur SWAPGO | C29: =IFERROR(VLOOKUP(B29,Liste!C1:D5,2,FALSE),"") -> 2500 | D29: =IFERROR(C29/4.33,0) -> 577.36721
A30: Semi (1) | B30: Remorque SWAP | C30: =IFERROR(VLOOKUP(B30,Liste!$C$7:$D$15,2,FALSE),"") -> 400 | D30: =IFERROR(C30/4.33,0) -> 92.378753
A31: Semi (2) | B31: AUCUNE | C31: =IFERROR(VLOOKUP(B31,Liste!$C$7:$D$15,2,FALSE),"") | D31: =IFERROR(C31/4.33,0) -> 0
A32: Semi (3) | B32: AUCUNE | C32: =IFERROR(VLOOKUP(B32,Liste!$C$7:$D$15,2,FALSE),"") | D32: =IFERROR(C32/4.33,0) -> 0
A33: Semi (4) | B33: AUCUNE | C33: =IFERROR(VLOOKUP(B33,Liste!$C$7:$D$15,2,FALSE),"") | D33: =IFERROR(C33/4.33,0) -> 0
A34: Carburant | B34: GO | C34: 1.3554 | D34: =(B11*D5/100)*C34 -> 1253.0402
A35: Carburant | B35: GNC | C35: 0 | D35: =(D5*B11/100)*C35 -> 0
A36: AD Blue | C36: 0.4309 | D36: =(D6*B11)*C36 -> 23.652532
A37: Fuel | C37: 1.1225
A38: Casse / Pneumatique / Lavage ( hors entretien) | C38: 0.04 | D38: =C38*B11 -> 115.56
A39: Autoroute | B39: =B12 -> 0 | C39: 5 | D39: =C39*B39 -> 0
A40: Salaires | B40: CM | C40: 1 | D40: 1000.54
A41: Frais Hotel | D41: =G11 -> 0
A42: Tirpalette | B42: NON | C42: =IF(B42=Liste!A24,Liste!B18,0) -> 0 | D42: =C42/4.33 -> 0
A43: Sous-Traitance | C43: 0 | D43: 0
...

Sheet CM14
A1: FICHE DE RENTABILITE
A3: DONNEES EXPLOITATION
B4: Immatriculation | D4: Conso au 100 (Moyenne) | F4: Semaine | G4: S16
A5: Tracteur (s) | B5: GC-623-YH | D5: 30.53
A6: Semi (s) | B6: Remorque | D6: 0.019
A7: Conducteurs | B7: BEZDIGA | C7: ANDRY
A8: AMPLITUDE Hebdo | B8: 65.31 | C8: 51.48
A9: TDS Hebdo | B9: 43.96 | C9: 45.53
B10: KM Hebdo | G10: Hotel (semaine)
B11: =2939+1157 -> 4096 | G11: 0
A12: Autoroute / jour : | B12: 136.16 | F12: SPL | G12: CM
E13: €/ Hebdo | F13: 1000 | G13: 1100
A14: Détails CA
A15: Référence prestations | B15: Fréquence | C15: Montant unitaire | D15: Quantité | E15: Total Hors IGO | F15: Indexation | G15: Montant Total
A16: Chronopost : 29802 | B16: Lundi => Vendredi | C16: 614 | D16: 5 | E16: =C16*D16 -> 3070 | F16: =(0.2922*452)*5 -> 660.372 | G16: =E16+F16 -> 3730.372
A17: COLISSIMO : IDFN-DOT-00A-CM | B17: Lundi => Vendredi | C17: 2.4411 | D17: =(60+50+42)*5 -> 760 | E17: =C17*D17 -> 1855.236 | F17: 0 | G17: =(E17*F17)+E17 -> 1855.236
A18: WE : (Bezdiga) VIAPOST 163-13/9 | B18: Dimanche | C18: =208.26+268.88 -> 477.14 | D18: 1 | E18: =C18*D18 -> 477.14 | F18: 0.039775 | G18: =(E18*F18)+E18 -> 496.11824
A19: WE : (Andry) Colissimo DOT-00A-CM | B19: Samedi | C19: 2.4411 | D19: =60+66 -> 126 | E19: =C19*D19 -> 307.5786 | G19: =(E19*F19)+E19 -> 307.5786
E20: =C20*D20 -> 0 | G20: =(E20*F20)+E20 -> 0
E21: =C21*D21 -> 0 | G21: =(E21*F21)+E21 -> 0
E22: =C22*D22 -> 0 | G22: =(E22*F22)+E22 -> 0
A24: CM14 | B24: CA DE LA LIGNE | F24: =SUM(G16:G22) -> 6389.3048
A25: SOMMAIRE
A27: Coûts de la Ligne
B28: Type | C28: unité | D28: Cout Semaine
A29: Moteur | B29: Porteur SWAPGNC | C29: =IFERROR(VLOOKUP(B29,Liste!C1:D5,2,FALSE),"") -> 3000 | D29: =IFERROR(C29/4.33,0) -> 692.84065
A30: Semi (1) | B30: Remorque SWAP | C30: =IFERROR(VLOOKUP(B30,Liste!$C$7:$D$15,2,FALSE),"") -> 400 | D30: =IFERROR(C30/4.33,0) -> 92.378753
A31: Semi (2) | B31: AUCUNE | C31: =IFERROR(VLOOKUP(B31,Liste!$C$7:$D$15,2,FALSE),"") | D31: =IFERROR(C31/4.33,0) -> 0
A32: Semi (3) | B32: AUCUNE | C32: =IFERROR(VLOOKUP(B32,Liste!$C$7:$D$15,2,FALSE),"") | D32: =IFERROR(C32/4.33,0) -> 0
A33: Semi (4) | B33: AUCUNE | C33: =IFERROR(VLOOKUP(B33,Liste!$C$7:$D$15,2,FALSE),"") | D33: =IFERROR(C33/4.33,0) -> 0
A34: Carburant | B34: GO | C34: 0 | D34: =(B11*D5/100)*C34 -> 0
A35: Carburant | B35: GNC | C35: 1.365 | D35: =(D5*B11/100)*C35 -> 1706.9445
A36: AD Blue | C36: 0 | D36: =(D6*B11)*C36 -> 0
A37: Fuel | C37: 1.1225
A38: Casse / Pneumatique / Lavage ( hors entretien) | C38: 0.04 | D38: =C38*B11 -> 163.84
A39: Autoroute | B39: =B12 -> 136.16 | C39: 5 | D39: =C39*B39 -> 680.8
A40: Salaires | B40: CM | C40: 2 | D40: =948.83+1030.95 -> 1979.78
A41: Frais Hotel | D41: =G11 -> 0
A42: Tirpalette | B42: NON | C42: =IF(B42=Liste!A24,Liste!B18,0) -> 0 | D42: =C42/4.33 -> 0
A43: Sous-Traitance | C43: 0 | D43: 0
...

Sheet CM15
A1: FICHE DE RENTABILITE
A3: DONNEES EXPLOITATION
B4: Immatriculation | D4: Conso au 100 (Moyenne) | F4: Semaine | G4: S16
A5: Tracteur (s) | B5: EJ-937-FF | D5: 24.17
A6: Semi (s) | B6: Remorque | D6: 0.019
A7: Conducteurs | B7: VIOREL
A8: AMPLITUDE Hebdo | B8: 71.05
A9: TDS Hebdo | B9: 33.51
B10: KM Hebdo | G10: Hotel (semaine)
B11: 1303 | G11: 0
A12: Autoroute / jour : | B12: 0 | F12: SPL | G12: CM
E13: €/ Hebdo | F13: 1000 | G13: 1100
A14: Détails CA
A15: Référence prestations | B15: Fréquence | C15: Montant unitaire | D15: Quantité | E15: Total Hors IGO | F15: Indexation | G15: Montant Total
A16: UPS : PA07 | B16: lundi => Vendredi | C16: 275 | D16: 5 | E16: =C16*D16 -> 1375 | F16: -0.0226 | G16: =(E16*F16)+E16 -> 1343.925
A17: Chronopost : 38853 | B17: lundi => Vendredi | C17: 198 | D17: 5 | E17: =C17*D17 -> 990 | F17: =(87*5)*0.2922 -> 127.107 | G17: =(E17+F17) -> 1117.107 | I17: Indexation gaz sur véhicule go
A18: WE : Colissimo LTH-004-CM | B18: Dimanche | C18: 4.1631 | D18: 10 | E18: =C18*D18 -> 41.631 | G18: =(E18*F18)+E18 -> 41.631
A19: WE : Colissimo LTH-081-CM | B19: Dimanche | C19: 2.4933 | D19: 74 | E19: =C19*D19 -> 184.5042 | G19: =(E19*F19)+E19 -> 184.5042
E20: =C20*D20 -> 0 | G20: =(E20*F20)+E20 -> 0
E21: =C21*D21 -> 0 | G21: =(E21*F21)+E21 -> 0
E22: =C22*D22 -> 0 | G22: =(E22*F22)+E22 -> 0
A24: CM15 | B24: CA DE LA LIGNE | F24: =SUM(G16:G22) -> 2687.1672
A25: SOMMAIRE
A27: Coûts de la Ligne
B28: Type | C28: unité | D28: Cout Semaine
A29: Moteur | B29: Porteur SWAPGO | C29: =IFERROR(VLOOKUP(B29,Liste!C1:D5,2,FALSE),"") -> 2500 | D29: =IFERROR(C29/4.33,0) -> 577.36721
A30: Semi (1) | B30: Remorque SWAP | C30: =IFERROR(VLOOKUP(B30,Liste!$C$7:$D$15,2,FALSE),"") -> 400 | D30: =IFERROR(C30/4.33,0) -> 92.378753
A31: Semi (2) | B31: AUCUNE | C31: =IFERROR(VLOOKUP(B31,Liste!$C$7:$D$15,2,FALSE),"") | D31: =IFERROR(C31/4.33,0) -> 0
A32: Semi (3) | B32: AUCUNE | C32: =IFERROR(VLOOKUP(B32,Liste!$C$7:$D$15,2,FALSE),"") | D32: =IFERROR(C32/4.33,0) -> 0
A33: Semi (4) | B33: AUCUNE | C33: =IFERROR(VLOOKUP(B33,Liste!$C$7:$D$15,2,FALSE),"") | D33: =IFERROR(C33/4.33,0) -> 0
A34: Carburant | B34: GO | C34: 1.3554 | D34: =(B11*D5/100)*C34 -> 426.86303
A35: Carburant | B35: GNC | D35: =(D5*B11/100)*C35 -> 0
A36: AD Blue | C36: 0.4309 | D36: =(D6*B11)*C36 -> 10.667791
A37: Fuel | C37: 1.1225
A38: Casse / Pneumatique / Lavage ( hors entretien) | C38: 0.04 | D38: =C38*B11 -> 52.12
A39: Autoroute | B39: =B12 -> 0 | C39: 5 | D39: =C39*B39 -> 0
A40: Salaires | B40: CM | C40: 1 | D40: 935.4
A41: Frais Hotel | D41: =G11 -> 0
A42: Tirpalette | B42: NON | C42: =IF(B42=Liste!A24,Liste!B18,0) -> 0 | D42: =C42/4.33 -> 0
A43: Sous-Traitance | C43: 0 | D43: 0
...

Sheet CM19
A1: FICHE DE RENTABILITE
A3: DONNEES EXPLOITATION
B4: Immatriculation | D4: Conso au 100 (Moyenne) | F4: Semaine | G4: S15
A5: Tracteur (s) | B5: FZ-654-JG | C5: FZ-643-JG | D5: 28.47
A6: Semi (s) | B6: Remorque | C6: Remorque | D6: 0.019
A7: Conducteurs | B7: TAHLA | C7: NAILI
A8: AMPLITUDE Hebdo | B8: 64.83 | C8: 51.97
A9: TDS Hebdo | B9: 41.6 | C9: 42.59
B10: KM Hebdo | G10: Hotel (semaine)
B11: =3615+2082 -> 5697 | G11: 0
A12: Autoroute / jour : | B12: 262.88 | F12: SPL | G12: CM
E13: €/ Hebdo | F13: 1000 | G13: 1100
A14: Détails CA
A15: Référence prestations | B15: Fréquence | C15: Montant unitaire | D15: Quantité | E15: Total Hors IGO | F15: Indexation | G15: Montant Total
A16: Chronopost : 29957 | B16: lundi => Vendredi | C16: 330 | D16: 5 | E16: =C16*D16 -> 1650 | F16: =(49.5*5)*0.2922 -> 72.3195 | G16: =(E16+F16) -> 1722.3195 | I16: Indexation Gaz - véhicule GO
A17: Chronopost : 29800 | B17: lundi => Vendredi | C17: 1398 | D17: 5 | E17: =C17*D17 -> 6990 | F17: =(1026*5)*0.2922 -> 1498.986 | G17: =(E17+F17) -> 8488.986
A18: Chronopost : 29092 | B18: lundi => Vendredi | C18: 170 | D18: 5 | E18: =C18*D18 -> 850 | F18: =(33*5)*0.2922 -> 48.213 | G18: =(E18+F18) -> 898.213
A19: Naili tourne sur 5 Jours | E19: =C19*D19 -> 0 | G19: =(E19*F19)+E19 -> 0
A20: WE : (Tahla) UPS Ramasse Evry | B20: Dimanche | C20: 197.5 | D20: 1 | E20: =C20*D20 -> 197.5 | F20: 0.0409 | G20: =(E20*F20)+E20 -> 205.57775
A21: WE : (Tahla) Chronopost 38920 | B21: Dimanche | C21: 300 | D21: 1 | E21: =C21*D21 -> 300 | F21: =0.2673*96 -> 25.6608 | G21: =F21+E21 -> 325.6608
A22: WE : (Tahla) Chronopost 29101 | B22: Dimanche | C22: 195 | D22: 1 | E22: =C22*D22 -> 195 | F22: =64*0.2922 -> 18.7008 | G22: =F22+E22 -> 213.7008
A24: CM19 | B24: CA DE LA LIGNE | F24: =SUM(G16:G22) -> 11854.458
A25: SOMMAIRE
A27: Coûts de la Ligne
B28: Type | C28: unité | D28: Cout Semaine
A29: Moteur(1) | B29: Porteur SWAPGO | C29: =IFERROR(VLOOKUP(B29,Liste!C1:D5,2,FALSE),"") -> 2500 | D29: =IFERROR(C29/4.33,0) -> 577.36721
A30: Moteur (2) | B30: Porteur SWAPGO | C30: =IFERROR(VLOOKUP(B30,Liste!C2:D6,2,FALSE),"") -> 2500 | D30: =IFERROR(C30/4.33,0) -> 577.36721
A31: Semi (1) | B31: Remorque SWAP | C31: =IFERROR(VLOOKUP(B31,Liste!$C$7:$D$15,2,FALSE),"") -> 400 | D31: =IFERROR(C31/4.33,0) -> 92.378753
A32: Semi (2) | B32: Remorque SWAP | C32: =IFERROR(VLOOKUP(B32,Liste!$C$7:$D$15,2,FALSE),"") -> 400 | D32: =IFERROR(C32/4.33,0) -> 92.378753
A33: Semi (3) | B33: AUCUNE | C33: =IFERROR(VLOOKUP(B33,Liste!$C$7:$D$15,2,FALSE),"") | D33: =IFERROR(C33/4.33,0) -> 0
A34: Semi (4) | B34: AUCUNE | C34: =IFERROR(VLOOKUP(B34,Liste!$C$7:$D$15,2,FALSE),"") | D34: =IFERROR(C34/4.33,0) -> 0
A35: Carburant | B35: GO | C35: 1.3554 | D35: =(B11*D5/100)*C35 -> 2198.3719
A36: Carburant | B36: GNC | C36: 0 | D36: =(D5*B11/100)*C36 -> 0
A37: AD Blue | C37: 0.4309 | D37: =(D6*B11)*C37 -> 46.641909
A38: Fuel | C38: 1.1225
A39: Casse / Pneumatique / Lavage ( hors entretien) | C39: 0.04 | D39: =C39*B11 -> 227.88
A40: Autoroute | B40: =B12 -> 262.88 | C40: 5 | D40: =(C40*B40)+11.5 -> 1325.9 | E40: rajout 11,50 pour le dimanche (montataire)
A41: Salaires | B41: CM | C41: 2 | D41: =1200.04+1418.11 -> 2618.15
A42: Frais Hotel | D42: =G11 -> 0
A43: Tirpalette | B43: NON | C43: =IF(B43=Liste!A24,Liste!B18,0) -> 0 | D43: =C43/4.33 -> 0
...

Sheet CM23
A1: FICHE DE RENTABILITE
A3: DONNEES EXPLOITATION
B4: Immatriculation | D4: Conso au 100 (Moyenne) | F4: Semaine | G4: S16
A5: Tracteur (s) | B5: FB-491-MH | D5: 29.18
A6: Semi (s) | B6: Remorque | D6: 0.019
A7: Conducteurs | B7: ANSEUR
A8: AMPLITUDE Hebdo | B8: 49.75
A9: TDS Hebdo | B9: 39.92
B10: KM Hebdo | G10: Hotel (semaine)
B11: 2301 | G11: 0
A12: Autoroute / jour : | B12: 170.9 | F12: SPL | G12: CM
E13: €/ Hebdo | F13: 1000 | G13: 1100
A14: Détails CA
A15: Référence prestations | B15: Fréquence | C15: Montant unitaire | D15: Quantité | E15: Total Hors IGO | F15: Indexation | G15: Montant Total
A16: CHRONOPOST : 38838 | B16: Lundi => Vendredi | C16: 211 | D16: 5 | E16: =C16*D16 -> 1055 | F16: =(165*5)*0.2922 -> 241.065 | G16: =(E16+F16) -> 1296.065 | I16: Indexation Gaz - véhicule GO
A17: CHRONOPOST : 38492 | B17: Lundi => Vendredi | C17: 289 | D17: 5 | E17: =C17*D17 -> 1445 | F17: =(225*5)*0.2922 -> 328.725 | G17: =(E17+F17) -> 1773.725
A18: Colissimo : LTH-017-CM | B18: Lundi => Vendredi | C18: 2.5021 | D18: =76*5 -> 380 | E18: =C18*D18 -> 950.798 | F18: 0 | G18: =(E18+F18) -> 950.798
A19: Tourne sur 5 jours | E19: =C19*D19 -> 0 | G19: =(E19*F19)+E19 -> 0
E20: =C20*D20 -> 0 | G20: =(E20*F20)+E20 -> 0
E21: =C21*D21 -> 0 | G21: =(E21*F21)+E21 -> 0
E22: =C22*D22 -> 0 | G22: =(E22*F22)+E22 -> 0
A24: CM23 | B24: CA DE LA LIGNE | F24: =SUM(G16:G22) -> 4020.588
A25: SOMMAIRE
A27: Coûts de la Ligne
B28: Type | C28: unité | D28: Cout Semaine
A29: Moteur(1) | B29: Porteur SWAPGO | C29: =IFERROR(VLOOKUP(B29,Liste!C1:D5,2,FALSE),"") -> 2500 | D29: =IFERROR(C29/4.33,0) -> 577.36721
A30: Semi (1) | B30: Remorque SWAP | C30: =IFERROR(VLOOKUP(B30,Liste!$C$7:$D$15,2,FALSE),"") -> 400 | D30: =IFERROR(C30/4.33,0) -> 92.378753
A31: Semi (2) | B31: AUCUNE | C31: =IFERROR(VLOOKUP(B31,Liste!$C$7:$D$15,2,FALSE),"") | D31: =IFERROR(C31/4.33,0) -> 0
A32: Semi (3) | B32: AUCUNE | C32: =IFERROR(VLOOKUP(B32,Liste!$C$7:$D$15,2,FALSE),"") | D32: =IFERROR(C32/4.33,0) -> 0
A33: Semi (4) | B33: AUCUNE | C33: =IFERROR(VLOOKUP(B33,Liste!$C$7:$D$15,2,FALSE),"") | D33: =IFERROR(C33/4.33,0) -> 0
A34: Carburant | B34: GO | C34: 1.3554 | D34: =(B11*D5/100)*C34 -> 910.05866
A35: Carburant | B35: GNC | C35: 0 | D35: =(D5*B11/100)*C35 -> 0
A36: AD Blue | C36: 0.4309 | D36: =(D6*B11)*C36 -> 18.838517
A37: Fuel | C37: 1.1225
A38: Casse / Pneumatique / Lavage ( hors entretien) | C38: 0.04 | D38: =C38*B11 -> 92.04
A39: Autoroute | B39: =B12 -> 170.9 | C39: 5 | D39: =C39*B39 -> 854.5
A40: Salaires | B40: CM | C40: 1 | D40: 1247.23
A41: Frais Hotel | D41: =G11 -> 0
A42: Tirpalette | B42: NON | C42: =IF(B42=Liste!A24,Liste!B18,0) -> 0 | D42: =C42/4.33 -> 0
A43: Sous-Traitance | C43: 0 | D43: 0
...

Sheet CM25
A1: FICHE DE RENTABILITE
A3: DONNEES EXPLOITATION
B4: Immatriculation | D4: Conso au 100 (Moyenne) | F4: Semaine | G4: S15
A5: Tracteur (s) | B5: EY-873-GA | D5: 35.09
A6: Semi (s) | B6: Remorque | D6: 0.019
A7: Conducteurs | B7: WAGNER
A8: AMPLITUDE Hebdo | B8: 47.91
A9: TDS Hebdo | B9: 40.62
B10: KM Hebdo | G10: Hotel (semaine)
B11: 2014 | G11: 0
A12: Autoroute / jour : | B12: 43 | F12: SPL | G12: CM
E13: €/ Hebdo | F13: 1000 | G13: 1100
A14: Détails CA
A15: Référence prestations | B15: Fréquence | C15: Montant unitaire | D15: Quantité | E15: Total Hors IGO | F15: Indexation | G15: Montant Total
A16: Chronopost Amiens Chilly 38468 | B16: Lundi au Vendredi | C16: 530 | D16: 5 | E16: =C16*D16 -> 2650 | F16: =(350*5)*0.2922 -> 511.35 | G16: =(E16+F16) -> 3161.35 | I16: Indexation Gaz - véhicule GO
A17: Chronopost Chilly Bobigny 29599 | B17: Lundi au Vendredi | C17: 160 | D17: 5 | E17: =C17*D17 -> 800 | F17: =(40*5)*0.2922 -> 58.44 | G17: =(E17+F17) -> 858.44
E18: =C18*D18 -> 0 | G18: =(E18+F18) -> 0
A19: Tourne sur 5 jours | E19: =C19*D19 -> 0 | G19: =(E19*F19)+E19 -> 0
E20: =C20*D20 -> 0 | G20: =(E20*F20)+E20 -> 0
E21: =C21*D21 -> 0 | G21: =(E21*F21)+E21 -> 0
E22: =C22*D22 -> 0 | G22: =(E22*F22)+E22 -> 0
A24: CM25 | B24: CA DE LA LIGNE | F24: =SUM(G16:G22) -> 4019.79
A25: SOMMAIRE
A27: Coûts de la Ligne
B28: Type | C28: unité | D28: Cout Semaine
A29: Moteur(1) | B29: Porteur SWAPGO | C29: =IFERROR(VLOOKUP(B29,Liste!C1:D5,2,FALSE),"") -> 2500 | D29: =IFERROR(C29/4.33,0) -> 577.36721
A30: Semi (1) | B30: Remorque SWAP | C30: =IFERROR(VLOOKUP(B30,Liste!$C$7:$D$15,2,FALSE),"") -> 400 | D30: =IFERROR(C30/4.33,0) -> 92.378753
A31: Semi (2) | B31: AUCUNE | C31: =IFERROR(VLOOKUP(B31,Liste!$C$7:$D$15,2,FALSE),"") | D31: =IFERROR(C31/4.33,0) -> 0
A32: Semi (3) | B32: AUCUNE | C32: =IFERROR(VLOOKUP(B32,Liste!$C$7:$D$15,2,FALSE),"") | D32: =IFERROR(C32/4.33,0) -> 0
A33: Semi (4) | B33: AUCUNE | C33: =IFERROR(VLOOKUP(B33,Liste!$C$7:$D$15,2,FALSE),"") | D33: =IFERROR(C33/4.33,0) -> 0
A34: Carburant | B34: GO | C34: 1.3554 | D34: =(B11*D5/100)*C34 -> 957.87826
A35: Carburant | B35: GNC | C35: 0 | D35: =(D5*B11/100)*C35 -> 0
A36: AD Blue | C36: 0.4309 | D36: =(D6*B11)*C36 -> 16.488819
A37: Fuel | C37: 1.1225
A38: Casse / Pneumatique / Lavage ( hors entretien) | C38: 0.04 | D38: =C38*B11 -> 80.56
A39: Autoroute | B39: =B12 -> 43 | C39: 5 | D39: =C39*B39 -> 215
A40: Salaires | B40: CM | C40: 1 | D40: 1028.42
A41: Frais Hotel | D41: =G11 -> 0
A42: Tirpalette | B42: NON | C42: =IF(B42=Liste!A24,Liste!B18,0) -> 0 | D42: =C42/4.33 -> 0
A43: Sous-Traitance | C43: 0 | D43: 0
...

Sheet CM26
A1: FICHE DE RENTABILITE
A3: DONNEES EXPLOITATION
B4: Immatriculation | D4: Conso au 100 (Moyenne) | F4: Semaine | G4: S16
A5: Tracteur (s) | B5: EJ-141-TS | D5: 30.66
A6: Semi (s) | B6: Remorque | D6: 0.019
A7: Conducteurs | B7: BENALI
A8: AMPLITUDE Hebdo | B8: 73.98
A9: TDS Hebdo | B9: 50.18
B10: KM Hebdo | G10: Hotel (semaine)
B11: 3591 | G11: 0
A12: Autoroute / jour : | B12: =45.75+136.5 -> 182.25 | F12: SPL | G12: CM
E13: €/ Hebdo | F13: 1000 | G13: 1100
A14: Détails CA
A15: Référence prestations | B15: Fréquence | C15: Montant unitaire | D15: Quantité | E15: Total Hors IGO | F15: Indexation | G15: Montant Total
A16: CHRONOPOST Arras Aulnay 38492 | B16: Lundi au vendredi | C16: 606 | D16: 5 | E16: =C16*D16 -> 3030 | F16: =(487*5)*0.2922 -> 711.507 | G16: =(E16+F16) -> 3741.507 | I16: Indexation Gaz - véhicule GO
A17: CHRONOPOST Arras Aulnay 38838 | B17: Lundi au vendredi | C17: 194 | D17: 5 | E17: =C17*D17 -> 970 | F17: =(165*5)*0.2922 -> 241.065 | G17: =(E17+F17) -> 1211.065
E18: =C18*D18 -> 0 | G18: =(E18+F18) -> 0
A19: Tourne sur 5 jours | E19: =C19*D19 -> 0 | G19: =(E19*F19)+E19 -> 0
E20: =C20*D20 -> 0 | G20: =(E20*F20)+E20 -> 0
E21: =C21*D21 -> 0 | G21: =(E21*F21)+E21 -> 0
E22: =C22*D22 -> 0 | G22: =(E22*F22)+E22 -> 0
A24: CM26 | B24: CA DE LA LIGNE | F24: =SUM(G16:G22) -> 4952.572
A25: SOMMAIRE
A27: Coûts de la Ligne
B28: Type | C28: unité | D28: Cout Semaine
A29: Moteur(1) | B29: Porteur SWAPGO | C29: =IFERROR(VLOOKUP(B29,Liste!C1:D5,2,FALSE),"") -> 2500 | D29: =IFERROR(C29/4.33,0) -> 577.36721
A30: Semi (1) | B30: Remorque SWAP | C30: =IFERROR(VLOOKUP(B30,Liste!$C$7:$D$15,2,FALSE),"") -> 400 | D30: =IFERROR(C30/4.33,0) -> 92.378753
A31: Semi (2) | B31: AUCUNE | C31: =IFERROR(VLOOKUP(B31,Liste!$C$7:$D$15,2,FALSE),"") | D31: =IFERROR(C31/4.33,0) -> 0
A32: Semi (3) | B32: AUCUNE | C32: =IFERROR(VLOOKUP(B32,Liste!$C$7:$D$15,2,FALSE),"") | D32: =IFERROR(C32/4.33,0) -> 0
A33: Semi (4) | B33: AUCUNE | C33: =IFERROR(VLOOKUP(B33,Liste!$C$7:$D$15,2,FALSE),"") | D33: =IFERROR(C33/4.33,0) -> 0
A34: Carburant | B34: GO | C34: 1.3554 | D34: =(B11*D5/100)*C34 -> 1492.2962
A35: Carburant | B35: GNC | C35: 0 | D35: =(D5*B11/100)*C35 -> 0
A36: AD Blue | C36: 0.4309 | D36: =(D6*B11)*C36 -> 29.399876
A37: Fuel | C37: 1.1225
A38: Casse / Pneumatique / Lavage ( hors entretien) | C38: 0.04 | D38: =C38*B11 -> 143.64
A39: Autoroute | B39: =B12 -> 182.25 | C39: 5 | D39: =C39*B39 -> 911.25
A40: Salaires | B40: CM | C40: 1 | D40: 1315.68
A41: Frais Hotel | D41: =G11 -> 0
A42: Tirpalette | B42: NON | C42: =IF(B42=Liste!A24,Liste!B18,0) -> 0 | D42: =C42/4.33 -> 0
A43: Sous-Traitance | C43: 0 | D43: 0
...

Sheet CM59
A1: FICHE DE RENTABILITE
A3: DONNEES EXPLOITATION
B4: Immatriculation | D4: Conso au 100 (Moyenne) | F4: Semaine | G4: S15
A5: Tracteur (s) | B5: GP-189-NY | D5: 34.84
A6: Semi (s) | B6: Remorque | D6: 0.019
A7: Conducteurs | B7: MOROAINU Mihail
A8: AMPLITUDE Hebdo | B8: 64
A9: TDS Hebdo | B9: 44.19
B10: KM Hebdo | G10: Hotel (semaine)
B11: 2036 | G11: 0
A12: Autoroute / jour : | B12: 33.98 | F12: SPL | G12: CM
E13: €/ Hebdo | F13: 1000 | G13: 1100
A14: Détails CA
A15: Référence prestations | B15: Fréquence | C15: Montant unitaire | D15: Quantité | E15: Total Hors IGO | F15: Indexation | G15: Montant Total
A16: CHRONOPOST : 38922 | B16: Lundi au vendredi | C16: 695 | D16: 5 | E16: =C16*D16 -> 3475 | F16: =(288*5)*0.2922 -> 420.768 | G16: =(E16+F16) -> 3895.768
A17: WE : Colissimo LTH-007-CM | B17: Samedi | C17: 2.5021 | D17: 103 | E17: =C17*D17 -> 257.7163 | F17: 0 | G17: =(E17*F17)+E17 -> 257.7163
A18: COLISSIMO : LTH-007-CM | B18: Jeudi & Vendredi | C18: 2.5021 | D18: =84*2 -> 168 | E18: =C18*D18 -> 420.3528 | F18: 0 | G18: =(E18+F18) -> 420.3528
E19: =C19*D19 -> 0 | G19: =(E19*F19)+E19 -> 0
E20: =C20*D20 -> 0 | G20: =(E20*F20)+E20 -> 0
E21: =C21*D21 -> 0 | G21: =(E21*F21)+E21 -> 0
E22: =C22*D22 -> 0 | G22: =(E22*F22)+E22 -> 0
A24: CM59 | B24: CA DE LA LIGNE | F24: =SUM(G16:G22) -> 4573.8371
A25: SOMMAIRE
A27: Coûts de la Ligne
B28: Type | C28: unité | D28: Cout Semaine
A29: Moteur(1) | B29: Porteur SWAPGNC | C29: =IFERROR(VLOOKUP(B29,Liste!C1:D5,2,FALSE),"") -> 3000 | D29: =IFERROR(C29/4.33,0) -> 692.84065
A30: Semi (1) | B30: Remorque SWAP | C30: =IFERROR(VLOOKUP(B30,Liste!$C$7:$D$15,2,FALSE),"") -> 400 | D30: =IFERROR(C30/4.33,0) -> 92.378753
A31: Semi (2) | B31: AUCUNE | C31: =IFERROR(VLOOKUP(B31,Liste!$C$7:$D$15,2,FALSE),"") | D31: =IFERROR(C31/4.33,0) -> 0
A32: Semi (3) | B32: AUCUNE | C32: =IFERROR(VLOOKUP(B32,Liste!$C$7:$D$15,2,FALSE),"") | D32: =IFERROR(C32/4.33,0) -> 0
A33: Semi (4) | B33: AUCUNE | C33: =IFERROR(VLOOKUP(B33,Liste!$C$7:$D$15,2,FALSE),"") | D33: =IFERROR(C33/4.33,0) -> 0
A34: Carburant | B34: GO | C34: 0 | D34: =(B11*D5/100)*C34 -> 0
A35: Carburant | B35: GNC | C35: 1.365 | D35: =(D5*B11/100)*C35 -> 968.25238
A36: AD Blue | C36: 0 | D36: =(D6*B11)*C36 -> 0
A37: Fuel | C37: 1.1225
A38: Casse / Pneumatique / Lavage ( hors entretien) | C38: 0.04 | D38: =C38*B11 -> 81.44
A39: Autoroute | B39: =B12 -> 33.98 | C39: 5 | D39: =(C39*B39) -> 169.9
A40: Salaires | B40: CM | C40: 1 | D40: 1230.07
A41: Frais Hotel | D41: =G11 -> 0
A42: Tirpalette | B42: NON | C42: =IF(B42=Liste!A24,Liste!B18,0) -> 0 | D42: =C42/4.33 -> 0
A43: Sous-Traitance | C43: 0 | D43: 0
...

Sheet CM60
A1: FICHE DE RENTABILITE
A3: DONNEES EXPLOITATION
B4: Immatriculation | D4: Conso au 100 (Moyenne) | F4: Semaine | G4: S16
A5: Tracteur (s) | B5: GC-075-RE | D5: 33.5
A6: Semi (s) | B6: Remorque | D6: 0.019
A7: Conducteurs | B7: MOROAINU ION
A8: AMPLITUDE Hebdo | B8: 63.08
A9: TDS Hebdo | B9: 54.09
B10: KM Hebdo | G10: Hotel (semaine)
B11: 1408 | G11: 0
A12: Autoroute / jour : | B12: 34.74 | F12: SPL | G12: CM
E13: €/ Hebdo | F13: 1000 | G13: 1100
A14: Détails CA
A15: Référence prestations | B15: Fréquence | C15: Montant unitaire | D15: Quantité | E15: Total Hors IGO | F15: Indexation | G15: Montant Total
A16: COLISSIMO : LTH-007-CM | B16: Lundi au vendredi | C16: 2.5021 | D16: =84+84+168+336+420 -> 1092 | E16: =C16*D16 -> 2732.2932 | F16: 0 | G16: =(E16+F16) -> 2732.2932
A17: WE : Colissimo LTH-007-CM | B17: Samedi | C17: 2.5021 | D17: 103 | E17: =C17*D17 -> 257.7163 | F17: 0 | G17: =(E17*F17)+E17 -> 257.7163
A19: Colissimo : LTH-004-CM | B19: Lundi au Vendredi | C19: 4.1631 | D19: =10*5 -> 50 | E19: =C19*D19 -> 208.155 | F19: 0 | G19: =(E19*F19)+E19 -> 208.155
E20: =C20*D20 -> 0 | G20: =(E20*F20)+E20 -> 0
E21: =C21*D21 -> 0 | G21: =(E21*F21)+E21 -> 0
E22: =C22*D22 -> 0 | G22: =(E22*F22)+E22 -> 0
A24: CM60 | B24: CA DE LA LIGNE | F24: =SUM(G16:G22) -> 3198.1645
A25: SOMMAIRE
A27: Coûts de la Ligne
B28: Type | C28: unité | D28: Cout Semaine
A29: Moteur(1) | B29: Porteur SWAPGNC | C29: =IFERROR(VLOOKUP(B29,Liste!C1:D5,2,FALSE),"") -> 3000 | D29: =IFERROR(C29/4.33,0) -> 692.84065
A30: Semi (1) | B30: Remorque SWAP | C30: =IFERROR(VLOOKUP(B30,Liste!$C$7:$D$15,2,FALSE),"") -> 400 | D30: =IFERROR(C30/4.33,0) -> 92.378753
A31: Semi (2) | B31: AUCUNE | C31: =IFERROR(VLOOKUP(B31,Liste!$C$7:$D$15,2,FALSE),"") | D31: =IFERROR(C31/4.33,0) -> 0
A32: Semi (3) | B32: AUCUNE | C32: =IFERROR(VLOOKUP(B32,Liste!$C$7:$D$15,2,FALSE),"") | D32: =IFERROR(C32/4.33,0) -> 0
A33: Semi (4) | B33: AUCUNE | C33: =IFERROR(VLOOKUP(B33,Liste!$C$7:$D$15,2,FALSE),"") | D33: =IFERROR(C33/4.33,0) -> 0
A34: Carburant | B34: GO | C34: 0 | D34: =(B11*D5/100)*C34 -> 0
A35: Carburant | B35: GNC | C35: 1.365 | D35: =(D5*B11/100)*C35 -> 643.8432
A36: AD Blue | C36: 0 | D36: =(D6*B11)*C36 -> 0
A37: Fuel | C37: 1.1225
A38: Casse / Pneumatique / Lavage ( hors entretien) | C38: 0.04 | D38: =C38*B11 -> 56.32
A39: Autoroute | B39: =B12 -> 34.74 | C39: 5 | D39: =13*9.16 -> 119.08
A40: Salaires | B40: CM | C40: 1 | D40: 1297.18
A41: Frais Hotel | D41: =G11 -> 0
A42: Tirpalette | B42: NON | C42: =IF(B42=Liste!A24,Liste!B18,0) -> 0 | D42: =C42/4.33 -> 0
A43: Sous-Traitance | C43: 0 | D43: 0
C45: TOTAL COUT | D45: =SUM(D29:D43) -> 2901.6426
...

Sheet CM48
A1: FICHE DE RENTABILITE
A3: DONNEES EXPLOITATION
B4: Immatriculation | D4: Conso au 100 (Moyenne) | F4: Semaine | G4: S15
A5: Tracteur (s) | B5: DM-332-AC | D5: 30.54
A6: Semi (s) | B6: Remorque | D6: 0.019
A7: Conducteurs | B7: BOUTCHIHI
A8: AMPLITUDE Hebdo | B8: 58.81
A9: TDS Hebdo | B9: 52.42
B10: KM Hebdo | G10: Hotel (semaine)
B11: 3121 | G11: 0
A12: Autoroute / jour : | B12: 165.76 | F12: SPL | G12: CM
E13: €/ Hebdo | F13: 1000 | G13: 1100
A14: Détails CA
A15: Référence prestations | B15: Fréquence | C15: Montant unitaire | D15: Quantité | E15: Total Hors IGO | F15: Indexation | G15: Montant Total
A16: UPS : Le Mans | B16: Lundi au Vendredi | C16: 800 | D16: 5 | E16: =C16*D16 -> 4000 | F16: -0.0226 | G16: =(E16*F16)+E16 -> 3909.6
E17: =C17*D17 -> 0 | G17: =(E17*F17)+E17 -> 0
A18: Tourne sur 5 jours | E18: =C18*D18 -> 0 | G18: =(E18*F18)+E18 -> 0
E19: =C19*D19 -> 0 | G19: =(E19*F19)+E19 -> 0
E20: =C20*D20 -> 0 | G20: =(E20*F20)+E20 -> 0
E21: =C21*D21 -> 0 | G21: =(E21*F21)+E21 -> 0
E22: =C22*D22 -> 0 | G22: =(E22*F22)+E22 -> 0
A24: CM48 | B24: CA DE LA LIGNE | F24: =SUM(G16:G22) -> 3909.6
A25: SOMMAIRE
A27: Coûts de la Ligne
B28: Type | C28: unité | D28: Cout Semaine
A29: Moteur(1) | B29: Porteur SWAPGO | C29: =IFERROR(VLOOKUP(B29,Liste!C1:D5,2,FALSE),"") -> 2500 | D29: =IFERROR(C29/4.33,0) -> 577.36721
A30: Semi (1) | B30: Remorque SWAP | C30: =IFERROR(VLOOKUP(B30,Liste!$C$7:$D$15,2,FALSE),"") -> 400 | D30: =IFERROR(C30/4.33,0) -> 92.378753
A31: Semi (2) | B31: AUCUNE | C31: =IFERROR(VLOOKUP(B31,Liste!$C$7:$D$15,2,FALSE),"") | D31: =IFERROR(C31/4.33,0) -> 0
A32: Semi (3) | B32: AUCUNE | C32: =IFERROR(VLOOKUP(B32,Liste!$C$7:$D$15,2,FALSE),"") | D32: =IFERROR(C32/4.33,0) -> 0
A33: Semi (4) | B33: AUCUNE | C33: =IFERROR(VLOOKUP(B33,Liste!$C$7:$D$15,2,FALSE),"") | D33: =IFERROR(C33/4.33,0) -> 0
A34: Carburant | B34: GO | C34: 1.3554 | D34: =(B11*D5/100)*C34 -> 1291.9041
A35: Carburant | B35: GNC | C35: 0 | D35: =(D5*B11/100)*C35 -> 0
A36: AD Blue | C36: 0.4309 | D36: =(D6*B11)*C36 -> 25.551939
A37: Fuel | C37: 1.1225
A38: Casse / Pneumatique / Lavage ( hors entretien) | C38: 0.04 | D38: =C38*B11 -> 124.84
A39: Autoroute | B39: =B12 -> 165.76 | C39: 5 | D39: =(C39*B39) -> 828.8
A40: Salaires | B40: CM | C40: 1 | D40: 977.57
A41: Frais Hotel | D41: =G11 -> 0
A42: Tirpalette | B42: NON | C42: =IF(B42=Liste!A24,Liste!B18,0) -> 0 | D42: =C42/4.33 -> 0
A43: Sous-Traitance | C43: 0 | D43: 0
...

Sheet CM42
A1: FICHE DE RENTABILITE
A3: DONNEES EXPLOITATION
B4: Immatriculation | D4: Conso au 100 (Moyenne) | F4: Semaine | G4: S16
A5: Tracteur (s) | B5: ED-021-WG | D5: 30.32
A6: Semi (s) | B6: Remorque | D6: 0.019
A7: Conducteurs | B7: MADANI
A8: AMPLITUDE Hebdo | B8: 54.18
A9: TDS Hebdo | B9: 42.12
B10: KM Hebdo | G10: Hotel (semaine)
B11: 2607 | G11: 0
A12: Autoroute / jour : | B12: 91.5 | F12: SPL | G12: CM
E13: €/ Hebdo | F13: 1000 | G13: 1100
A14: Détails CA
A15: Référence prestations | B15: Fréquence | C15: Montant unitaire | D15: Quantité | E15: Total Hors IGO | F15: Indexation | G15: Montant Total
A16: UPS : Lesquin | B16: Lundi au Vendredi | C16: 680 | D16: 5 | E16: =C16*D16 -> 3400 | F16: -0.0226 | G16: =(E16*F16)+E16 -> 3323.16
E17: =C17*D17 -> 0 | G17: =(E17*F17)+E17 -> 0
A18: Tourne sur 5 jours | E18: =C18*D18 -> 0 | G18: =(E18*F18)+E18 -> 0
E19: =C19*D19 -> 0 | G19: =(E19*F19)+E19 -> 0
E20: =C20*D20 -> 0 | G20: =(E20*F20)+E20 -> 0
E21: =C21*D21 -> 0 | G21: =(E21*F21)+E21 -> 0
E22: =C22*D22 -> 0 | G22: =(E22*F22)+E22 -> 0
A24: CM42 | B24: CA DE LA LIGNE | F24: =SUM(G16:G22) -> 3323.16
A25: SOMMAIRE
A27: Coûts de la Ligne
B28: Type | C28: unité | D28: Cout Semaine
A29: Moteur(1) | B29: Porteur SWAPGO | C29: =IFERROR(VLOOKUP(B29,Liste!C1:D5,2,FALSE),"") -> 2500 | D29: =IFERROR(C29/4.33,0) -> 577.36721
A30: Semi (1) | B30: Remorque SWAP | C30: =IFERROR(VLOOKUP(B30,Liste!$C$7:$D$15,2,FALSE),"") -> 400 | D30: =IFERROR(C30/4.33,0) -> 92.378753
A31: Semi (2) | B31: AUCUNE | C31: =IFERROR(VLOOKUP(B31,Liste!$C$7:$D$15,2,FALSE),"") | D31: =IFERROR(C31/4.33,0) -> 0
A32: Semi (3) | B32: AUCUNE | C32: =IFERROR(VLOOKUP(B32,Liste!$C$7:$D$15,2,FALSE),"") | D32: =IFERROR(C32/4.33,0) -> 0
A33: Semi (4) | B33: AUCUNE | C33: =IFERROR(VLOOKUP(B33,Liste!$C$7:$D$15,2,FALSE),"") | D33: =IFERROR(C33/4.33,0) -> 0
A34: Carburant | B34: GO | C34: 1.3554 | D34: =(B11*D5/100)*C34 -> 1071.3656
A35: Carburant | B35: GNC | C35: 0 | D35: =(D5*B11/100)*C35 -> 0
A36: AD Blue | C36: 0.4309 | D36: =(D6*B11)*C36 -> 21.34377
A37: Fuel | C37: 1.1225
A38: Casse / Pneumatique / Lavage ( hors entretien) | C38: 0.04 | D38: =C38*B11 -> 104.28
A39: Autoroute | B39: =B12 -> 91.5 | C39: 5 | D39: =(C39*B39) -> 457.5
A40: Salaires | B40: CM | C40: 1 | D40: 1093.27
A41: Frais Hotel | D41: =G11 -> 0
A42: Tirpalette | B42: NON | C42: =IF(B42=Liste!A24,Liste!B18,0) -> 0 | D42: =C42/4.33 -> 0
A43: Sous-Traitance | C43: 0 | D43: 0
...

Sheet CM41
A1: FICHE DE RENTABILITE
A3: DONNEES EXPLOITATION
